<?xml version='1.0' encoding='utf-8'?>
<mujoco model="phoebe_left_arm">
  <compiler angle="radian" meshdir="/home/yaashia/phoebe_bridgeback_ws/src/phoebe_bridgeback/phoebe_mujoco_config/description/assets" fusestatic="false" />
  <option integrator="implicitfast" />
  <default>
    <default class="phoebe">
      <material specular="0.5" shininess="0.25" />
      <joint axis="0 1 0" range="-6.28319 6.28319" armature="0.1" />
      <position ctrlrange="-6.2831 6.2831" />
      <general biastype="affine" ctrlrange="-6.2831 6.2831" />
      <default class="size4">
        <joint damping="10" />
        <general forcerange="-330 330" gainprm="100000" biasprm="0 -100000 -10000" />
      </default>
      <default class="size3">
        <joint damping="5" />
        <general forcerange="-150 150" gainprm="40000" biasprm="0 -40000 -4000" />
        <default class="size3_limited">
          <joint range="-3.1415 3.1415" />
          <general ctrlrange="-3.1415 3.1415" />
        </default>
      </default>
      <default class="size2">
        <joint damping="2" />
        <general forcerange="-56 56" gainprm="10000" biasprm="0 -10000 -1000" />
      </default>
      <default class="hande">
        <joint damping="2" />
        <general forcerange="-50 50" ctrlrange="0.0 0.025" gainprm="1000" biasprm="0 -1000 -100" />
      </default>
      <default class="visual">
        <geom group="2" type="mesh" contype="0" conaffinity="0" />
      </default>
      <default class="collision">
        <geom group="3" type="mesh" />
      </default>
    </default>
  </default>
  <asset>
    <material name="Black.001" specular="0.5" shininess="0.25" rgba="0.033102 0.033102 0.033102 1.000000" />
    <material name="Black.002" specular="0.5" shininess="0.25" rgba="0.033102 0.033102 0.033102 1.000000" />
    <material name="Black.003" specular="0.5" shininess="0.25" rgba="0.033102 0.033102 0.033102 1.000000" />
    <material name="Black.004" specular="0.5" shininess="0.25" rgba="0.033102 0.033102 0.033102 1.000000" />
    <material name="Black.005" specular="0.5" shininess="0.25" rgba="0.033102 0.033102 0.033102 1.000000" />
    <material name="DEFAULT_MTL" specular="0.0" shininess="0.25" rgba="0.100000 0.100000 0.100000 1.000000" />
    <material name="DEFAULT_MTL.001" specular="0.0" shininess="0.25" rgba="0.800000 0.800000 0.800000 1.000000" />
    <material name="DEFAULT_MTL.002" specular="0.0" shininess="0.25" rgba="0.100000 0.100000 0.100000 1.000000" />
    <material name="JointGrey.001" specular="0.5" shininess="0.25" rgba="0.278431 0.278431 0.278431 1.000000" />
    <material name="JointGrey.002" specular="0.5" shininess="0.25" rgba="0.278431 0.278431 0.278431 1.000000" />
    <material name="JointGrey.003" specular="0.5" shininess="0.25" rgba="0.278431 0.278431 0.278431 1.000000" />
    <material name="JointGrey.004" specular="0.5" shininess="0.25" rgba="0.278431 0.278431 0.278431 1.000000" />
    <material name="JointGrey.005" specular="0.5" shininess="0.25" rgba="0.278431 0.278431 0.278431 1.000000" />
    <material name="LinkGrey" specular="0.5" shininess="0.25" rgba="0.820392 0.820392 0.820392 1.000000" />
    <material name="LinkGrey.001" specular="0.5" shininess="0.25" rgba="0.820392 0.820392 0.820392 1.000000" />
    <material name="LinkGrey.002" specular="0.5" shininess="0.25" rgba="0.820392 0.820392 0.820392 1.000000" />
    <material name="URBlue" specular="0.5" shininess="0.25" rgba="0.490196 0.678431 0.800000 1.000000" />
    <material name="URBlue.001" specular="0.5" shininess="0.25" rgba="0.490196 0.678431 0.800000 1.000000" />
    <material name="URBlue.002" specular="0.5" shininess="0.25" rgba="0.490196 0.678431 0.800000 1.000000" />
    <material name="URBlue.003" specular="0.5" shininess="0.25" rgba="0.490196 0.678431 0.800000 1.000000" />
    <material name="URBlue.004" specular="0.5" shininess="0.25" rgba="0.490196 0.678431 0.800000 1.000000" />
    <material name="new_mat_color.021" specular="0.5" shininess="0.36" rgba="0.100000 0.100000 0.100000 1.000000" />
    <mesh file="full/forearm/forearm_0.obj" scale="1.0 1.0 1.0" />
    <mesh file="full/forearm/forearm_1.obj" scale="1.0 1.0 1.0" />
    <mesh file="full/forearm/forearm_2.obj" scale="1.0 1.0 1.0" />
    <mesh file="full/forearm/forearm_3.obj" scale="1.0 1.0 1.0" />
    <mesh file="full/hande/hande.obj" scale="0.001 0.001 0.001" />
    <mesh file="full/ich-005_realsense_cable_mount_corr/ich-005_realsense_cable_mount_corr.obj" scale="0.0254 0.0254 0.0254" />
    <mesh file="full/mtc_effector_side/mtc_effector_side.obj" scale="1.0 1.0 1.0" />
    <mesh file="full/mtc_robot_side/mtc_robot_side.obj" scale="1.0 1.0 1.0" />
    <mesh file="full/robotiq_hande_cb_adapter/robotiq_hande_cb_adapter.obj" scale="1.0 1.0 1.0" />
    <mesh file="full/shoulder/shoulder_0.obj" scale="1.0 1.0 1.0" />
    <mesh file="full/shoulder/shoulder_1.obj" scale="1.0 1.0 1.0" />
    <mesh file="full/shoulder/shoulder_2.obj" scale="1.0 1.0 1.0" />
    <mesh file="full/upperarm/upperarm_0.obj" scale="1.0 1.0 1.0" />
    <mesh file="full/upperarm/upperarm_1.obj" scale="1.0 1.0 1.0" />
    <mesh file="full/upperarm/upperarm_2.obj" scale="1.0 1.0 1.0" />
    <mesh file="full/upperarm/upperarm_3.obj" scale="1.0 1.0 1.0" />
    <mesh file="full/wrist1/wrist1_0.obj" scale="1.0 1.0 1.0" />
    <mesh file="full/wrist1/wrist1_1.obj" scale="1.0 1.0 1.0" />
    <mesh file="full/wrist1/wrist1_2.obj" scale="1.0 1.0 1.0" />
    <mesh file="full/wrist2/wrist2_0.obj" scale="1.0 1.0 1.0" />
    <mesh file="full/wrist2/wrist2_1.obj" scale="1.0 1.0 1.0" />
    <mesh file="full/wrist2/wrist2_2.obj" scale="1.0 1.0 1.0" />
    <mesh file="full/wrist3/wrist3.obj" scale="1.0 1.0 1.0" />
  </asset>
  <worldbody>
    <body name="left_ur_arm_shoulder_link_mount" pos="0 0.201 0.85" quat="1 0 0 0">
      <body name="left_ur_arm_shoulder_link" pos="0.0126802 0.124615 0.463459" quat="0.353086 -0.134633 0.350748 0.856843">
        <inertial pos="0 -0.00193 -0.02561" quat="0.560239 0.250606 -0.316559 0.72327" mass="3.761" diaginertia="0.00703079 0.0070003 0.00602478" />
        <joint name="left_ur_arm_shoulder_pan_joint" pos="0 0 0" axis="0 0 1" range="-6.28319 6.28319" actuatorfrcrange="-150 150" />
        <body name="left_ur_arm_upper_arm_link" pos="0.000226782 0 0" quat="0.707115 0.707098 -9.55133e-07 -9.55157e-07">
          <inertial pos="-0.2125 0 0.11336" quat="0.500275 0.499641 0.500368 0.499716" mass="8.058" diaginertia="0.333881 0.332472 0.0150588" />
          <joint name="left_ur_arm_shoulder_lift_joint" pos="0 0 0" axis="0 0 1" range="-6.28319 6.28319" actuatorfrcrange="-150 150" />
          <body name="left_ur_arm_forearm_link" pos="-0.425505 0 0" quat="1 2.07226e-05 -0.000262987 -7.61405e-08">
            <inertial pos="-0.2422 0 0.0265" quat="0.501301 0.498381 0.510711 0.489375" mass="2.846" diaginertia="0.0787927 0.0785102 0.00397103" />
            <joint name="left_ur_arm_elbow_joint" pos="0 0 0" axis="0 0 1" range="-3.14159 3.14159" actuatorfrcrange="-150 150" />
            <body name="left_ur_arm_wrist_1_link" pos="-0.392582 -4.63122e-05 0.133721" quat="1 0.000173166 0.000544517 1.77883e-06">
              <inertial pos="0 -0.01634 -0.0018" quat="0.960609 0.277707 0.00515042 -0.00913626" mass="1.37" diaginertia="0.00165502 0.00142363 0.00119868" />
              <joint name="left_ur_arm_wrist_1_joint" pos="0 0 0" axis="0 0 1" range="-6.28319 6.28319" actuatorfrcrange="-28 28" />
              <body name="left_ur_arm_wrist_2_link" pos="1.36989e-05 -0.0999777 8.48591e-05" quat="0.707407 0.706807 -4.64337e-08 -4.64731e-08">
                <inertial pos="0 0.01634 -0.0018" quat="0.996652 -0.0779336 -0.00684629 -0.0237381" mass="1.3" diaginertia="0.00135637 0.00128607 0.00095814" />
                <joint name="left_ur_arm_wrist_2_joint" pos="0 0 0" axis="0 0 1" range="-6.28319 6.28319" actuatorfrcrange="-28 28" />
                <body name="left_ur_arm_wrist_3_link" pos="0.000106733 0.0996158 1.94962e-05" quat="-0.707176 0.707038 1.93623e-08 -1.93661e-08">
                  <inertial pos="0.000839754 -0.00316796 0.065463" quat="0.724907 0.688778 0.0074684 0.00631936" mass="1.31087" diaginertia="0.00765268 0.0049038 0.00405629" />
                  <joint name="left_ur_arm_wrist_3_joint" pos="0 0 0" axis="0 0 1" range="-6.28319 6.28319" actuatorfrcrange="-28 28" />
                  <geom material="LinkGrey.002" mesh="wrist3" class="visual" pos="0 0 -0.0989" quat="0.707107 0.707107 0 0" />
                  <geom mesh="wrist3" class="collision" pos="0 0 -0.0989" quat="0.707107 0.707107 0 0" />
                  <geom material="DEFAULT_MTL" mesh="mtc_robot_side" class="visual" pos="" quat="0 0 0 1" />
                  <geom mesh="mtc_robot_side" class="collision" pos="" quat="0 0 0 1" />
                  <geom material="DEFAULT_MTL.002" mesh="mtc_effector_side" class="visual" pos="0 0 0.009" quat="0 0 0 1" />
                  <geom mesh="mtc_effector_side" class="collision" pos="0 0 0.009" quat="0 0 0 1" />
                  <geom material="new_mat_color.021" mesh="ich-005_realsense_cable_mount_corr" class="visual" pos="0 0 0.033" quat="-0.707107 0 0 0.707107" />
                  <geom mesh="ich-005_realsense_cable_mount_corr" class="collision" pos="0 0 0.033" quat="-0.707107 0 0 0.707107" />
                  <geom material="DEFAULT_MTL.001" mesh="robotiq_hande_cb_adapter" class="visual" pos="0 0 0.036" quat="-1 0 0 0" />
                  <geom mesh="robotiq_hande_cb_adapter" class="collision" pos="0 0 0.036" quat="-1 0 0 0" />
                  <geom mesh="hande" class="visual" pos="0 0 0.047" quat="-1 0 0 0" />
                  <geom mesh="hande" class="collision" pos="0 0 0.047" quat="-1 0 0 0" />
                  <geom size="0.012525 0.045 0.0125" pos="0.000178732 0.0759414 0.0578834" quat="-0.53321 0.471099 0.468121 0.524037" type="box" class="collision" />
                  <geom size="0.012525 0.045 0.0125" pos="0.000178732 0.0759414 0.0578834" quat="-0.53321 0.471099 0.468121 0.524037" type="box" class="visual" />
                  <site name="left_ur_arm_wrist_3_link" pos="0 0 0" quat="1.0 0 0 0" />
                  <site name="left_ur_arm_ft_frame" pos="0 0 0" quat="0 1.0 0 0" />
                  <site name="left_ur_arm_flange" pos="0 0 0" quat="-0.5000000000000001 0.5 0.5000000000000001 0.49999999999999994" />
                  <site name="left_ur_arm_tool0" pos="0 0 0" quat="1.0 0 0 0" />
                  <site name="left_mtc_robot_side" pos="0 0 0" quat="0 0 0 1.0" />
                  <site name="left_mtc_effector_side" pos="0 0 0.009" quat="0 0 0 1.0" />
                  <site name="left_ur_realsense_mount" pos="0 0 0.033" quat="0.7071067811865475 0 0 -0.7071067811865476" />
                  <site name="left_wrist_mounted_camera_bottom_screw_frame" pos="0.00011461581058039112 0.06477723247500103 0.04588481485344156" quat="0.5332101511675295 -0.4710992667519285 -0.46812105206923166 -0.5240373041752767" />
                  <site name="left_wrist_mounted_camera_link" pos="0.01767710423050336 0.07606221192742246 0.05767753461007523" quat="0.5332101511675295 -0.4710992667519285 -0.46812105206923166 -0.5240373041752767" />
                  <site name="left_wrist_mounted_camera_depth_frame" pos="0.01767710423050336 0.07606221192742246 0.05767753461007523" quat="0.5332101511675295 -0.4710992667519285 -0.46812105206923166 -0.5240373041752767" />
                  <site name="left_wrist_mounted_camera_depth_optical_frame" pos="0.01767710423050336 0.07606221192742246 0.05767753461007523" quat="-0.00309731615477802 0.006075530837474827 -0.05901356826082302 0.9982338870819831" />
                  <site name="left_wrist_mounted_camera_infra1_frame" pos="0.01767710423050336 0.07606221192742246 0.05767753461007523" quat="0.5332101511675295 -0.4710992667519285 -0.46812105206923166 -0.5240373041752767" />
                  <site name="left_wrist_mounted_camera_infra1_optical_frame" pos="0.01767710423050336 0.07606221192742246 0.05767753461007523" quat="-0.00309731615477802 0.006075530837474827 -0.05901356826082302 0.9982338870819831" />
                  <site name="left_wrist_mounted_camera_infra2_frame" pos="-0.03231824522526468 0.07571717345757206 0.05826573631864059" quat="0.5332101511675295 -0.4710992667519285 -0.46812105206923166 -0.5240373041752767" />
                  <site name="left_wrist_mounted_camera_infra2_optical_frame" pos="-0.03231824522526468 0.07571717345757206 0.05826573631864059" quat="-0.00309731615477802 0.006075530837474827 -0.05901356826082302 0.9982338870819831" />
                  <site name="left_wrist_mounted_camera_color_frame" pos="0.03267570906723376 0.07616572346837758 0.05750107409750563" quat="0.5332101511675295 -0.4710992667519285 -0.46812105206923166 -0.5240373041752767" />
                  <site name="left_wrist_mounted_camera_color_optical_frame" pos="0.03267570906723376 0.07616572346837758 0.05750107409750563" quat="-0.00309731615477802 0.006075530837474827 -0.05901356826082302 0.9982338870819831" />
                  <site name="left_robotiq_hande_cb_adapter" pos="0 0 0.036" quat="1.0 0 0 0" />
                  <site name="left_gripper_base_link" pos="0 0 0.047" quat="1.0 0 0 0" />
                  <site name="left_gripper_palm_link" pos="0 0 0.1458" quat="1.0 0 0 0" />
                  <camera name="left_wrist_mounted_camera" fovy="58" mode="fixed" resolution="640 480" pos="0.03267570906723376 0.07616572346837758 0.05750107409750563" quat="-0.006075530837474827 -0.00309731615477802 0.9982338870819831 0.05901356826082302" />
                </body>
                <geom mesh="wrist2_0" material="Black.005" class="visual" pos="0 0 -0.0997" quat="1 0 0 0" />
                <geom mesh="wrist2_1" material="URBlue.004" class="visual" pos="0 0 -0.0997" quat="1 0 0 0" />
                <geom mesh="wrist2_2" material="JointGrey.005" class="visual" pos="0 0 -0.0997" quat="1 0 0 0" />
                <geom mesh="wrist2_0" class="collision" pos="0 0 -0.0997" quat="1 0 0 0" />
                <geom mesh="wrist2_1" class="collision" pos="0 0 -0.0997" quat="1 0 0 0" />
                <geom mesh="wrist2_2" class="collision" pos="0 0 -0.0997" quat="1 0 0 0" />
                <site name="left_ur_arm_wrist_2_link" pos="0 0 0" quat="1.0 0 0 0" />
              </body>
              <geom mesh="wrist1_0" material="Black.004" class="visual" pos="0 0 -0.127" quat="0.707107 0.707107 0 0" />
              <geom mesh="wrist1_1" material="URBlue.003" class="visual" pos="0 0 -0.127" quat="0.707107 0.707107 0 0" />
              <geom mesh="wrist1_2" material="JointGrey.004" class="visual" pos="0 0 -0.127" quat="0.707107 0.707107 0 0" />
              <geom mesh="wrist1_0" class="collision" pos="0 0 -0.127" quat="0.707107 0.707107 0 0" />
              <geom mesh="wrist1_1" class="collision" pos="0 0 -0.127" quat="0.707107 0.707107 0 0" />
              <geom mesh="wrist1_2" class="collision" pos="0 0 -0.127" quat="0.707107 0.707107 0 0" />
              <site name="left_ur_arm_wrist_1_link" pos="0 0 0" quat="1.0 0 0 0" />
            </body>
            <geom mesh="forearm_0" material="URBlue.002" class="visual" pos="0 0 0.007" quat="0.5 0.5 -0.5 -0.5" />
            <geom mesh="forearm_1" material="LinkGrey.001" class="visual" pos="0 0 0.007" quat="0.5 0.5 -0.5 -0.5" />
            <geom mesh="forearm_2" material="Black.003" class="visual" pos="0 0 0.007" quat="0.5 0.5 -0.5 -0.5" />
            <geom mesh="forearm_3" material="JointGrey.003" class="visual" pos="0 0 0.007" quat="0.5 0.5 -0.5 -0.5" />
            <geom mesh="forearm_0" class="collision" pos="0 0 0.007" quat="0.5 0.5 -0.5 -0.5" />
            <geom mesh="forearm_1" class="collision" pos="0 0 0.007" quat="0.5 0.5 -0.5 -0.5" />
            <geom mesh="forearm_2" class="collision" pos="0 0 0.007" quat="0.5 0.5 -0.5 -0.5" />
            <geom mesh="forearm_3" class="collision" pos="0 0 0.007" quat="0.5 0.5 -0.5 -0.5" />
            <site name="left_ur_arm_forearm_link" pos="0 0 0" quat="1.0 0 0 0" />
          </body>
          <geom mesh="upperarm_0" material="LinkGrey" class="visual" pos="0 0 0.138" quat="0.5 0.5 -0.5 -0.5" />
          <geom mesh="upperarm_1" material="Black.002" class="visual" pos="0 0 0.138" quat="0.5 0.5 -0.5 -0.5" />
          <geom mesh="upperarm_2" material="JointGrey.002" class="visual" pos="0 0 0.138" quat="0.5 0.5 -0.5 -0.5" />
          <geom mesh="upperarm_3" material="URBlue.001" class="visual" pos="0 0 0.138" quat="0.5 0.5 -0.5 -0.5" />
          <geom mesh="upperarm_0" class="collision" pos="0 0 0.138" quat="0.5 0.5 -0.5 -0.5" />
          <geom mesh="upperarm_1" class="collision" pos="0 0 0.138" quat="0.5 0.5 -0.5 -0.5" />
          <geom mesh="upperarm_2" class="collision" pos="0 0 0.138" quat="0.5 0.5 -0.5 -0.5" />
          <geom mesh="upperarm_3" class="collision" pos="0 0 0.138" quat="0.5 0.5 -0.5 -0.5" />
          <site name="left_ur_arm_upper_arm_link" pos="0 0 0" quat="1.0 0 0 0" />
        </body>
        <geom mesh="shoulder_0" material="URBlue" class="visual" pos="" quat="0 0 0 1" />
        <geom mesh="shoulder_1" material="Black.001" class="visual" pos="" quat="0 0 0 1" />
        <geom mesh="shoulder_2" material="JointGrey.001" class="visual" pos="" quat="0 0 0 1" />
        <geom mesh="shoulder_0" class="collision" pos="" quat="0 0 0 1" />
        <geom mesh="shoulder_1" class="collision" pos="" quat="0 0 0 1" />
        <geom mesh="shoulder_2" class="collision" pos="" quat="0 0 0 1" />
        <site name="left_ur_arm_shoulder_link" pos="0 0 0" quat="1.0 0 0 0" />
      </body>
    </body>
  </worldbody>
</mujoco>
