<?xml version="1.0" ?>
<mujoco model="phoebe">
  <compiler angle="radian" meshdir="assets/"/>
  <asset>
    <mesh file="full/body/body.obj" scale="1.0 1.0 1.0"/>
    <material name="new_mat_color" specular="0.5" shininess="0.36" rgba="0.150000 0.150000 0.150000 1.000000"/>
    <mesh file="full/side-cover/side-cover.obj" scale="1.0 1.0 1.0"/>
    <material name="new_mat_color.001" specular="0.5" shininess="0.36" rgba="0.800000 0.800000 0.000000 1.000000"/>
    <mesh file="full/end-cover/end-cover.obj" scale="1.0 1.0 1.0"/>
    <material name="new_mat_color.002" specular="0.5" shininess="0.36" rgba="0.150000 0.150000 0.150000 1.000000"/>
    <mesh file="full/lights/lights.obj" scale="1.0 1.0 1.0"/>
    <material name="new_mat_color.003" specular="0.5" shininess="0.36" rgba="1.000000 1.000000 1.000000 1.000000"/>
    <mesh file="full/axle/axle.obj" scale="1.0 1.0 1.0"/>
    <material name="new_mat_color.004" specular="0.5" shininess="0.36" rgba="0.150000 0.150000 0.150000 1.000000"/>
    <mesh file="full/top/top.obj" scale="1.0 1.0 1.0"/>
    <material name="new_mat_color.005" specular="0.5" shininess="0.36" rgba="0.150000 0.150000 0.150000 1.000000"/>
    <mesh file="full/rocker/rocker.obj" scale="1.0 1.0 1.0"/>
    <material name="new_mat_color.006" specular="0.5" shininess="0.36" rgba="0.150000 0.150000 0.150000 1.000000"/>
    <mesh file="full/wheel/wheel.obj" scale="1.0 1.0 1.0"/>
    <material name="new_mat_color.007" specular="0.5" shininess="0.36" rgba="0.150000 0.150000 0.150000 1.000000"/>
    <mesh file="full/lift_rails/lift_rails.obj" scale="1.0 1.0 1.0"/>
    <material name="new_mat_color.008" specular="0.5" shininess="0.36" rgba="0.150000 0.150000 0.150000 1.000000"/>
    <mesh file="full/shelf/shelf.obj" scale="1.0 1.0 1.0"/>
    <material name="new_mat_color.009" specular="0.5" shininess="0.36" rgba="0.150000 0.150000 0.150000 1.000000"/>
    <mesh file="full/monitor_hinge_base/monitor_hinge_base.obj" scale="1.0 1.0 1.0"/>
    <material name="new_mat_color.010" specular="0.5" shininess="0.36" rgba="0.150000 0.150000 0.150000 1.000000"/>
    <mesh file="full/monitor_hinge_top/monitor_hinge_top.obj" scale="1.0 1.0 1.0"/>
    <material name="new_mat_color.011" specular="0.5" shininess="0.36" rgba="0.150000 0.150000 0.150000 1.000000"/>
    <mesh file="full/monitor/monitor.obj" scale="1.0 1.0 1.0"/>
    <material name="new_mat_color.012" specular="0.5" shininess="0.36" rgba="0.150000 0.150000 0.150000 1.000000"/>
    <mesh file="full/scu/scu.obj" scale="1.0 1.0 1.0"/>
    <material name="new_mat_color.013" specular="0.5" shininess="0.36" rgba="0.500000 0.500000 0.500000 1.000000"/>
    <mesh file="full/autec_receiver/autec_receiver.obj" scale="1.0 1.0 1.0"/>
    <material name="new_mat_color.014" specular="0.5" shininess="0.36" rgba="0.800000 0.800000 0.000000 1.000000"/>
    <mesh file="full/wifi_antenna/wifi_antenna.obj" scale="1.0 1.0 1.0"/>
    <material name="new_mat_color.015" specular="0.5" shininess="0.36" rgba="0.150000 0.150000 0.150000 1.000000"/>
    <mesh file="full/autec_antenna/autec_antenna.obj" scale="1.0 1.0 1.0"/>
    <material name="new_mat_color.016" specular="0.5" shininess="0.36" rgba="0.150000 0.150000 0.150000 1.000000"/>
    <mesh file="full/lift_low_500mm/lift_low_500mm.obj" scale="1.0 1.0 1.0"/>
    <material name="new_mat_color.017" specular="0.5" shininess="0.36" rgba="0.850000 0.850000 0.850000 1.000000"/>
    <mesh file="full/lift_mid_500mm/lift_mid_500mm.obj" scale="1.0 1.0 1.0"/>
    <material name="new_mat_color.018" specular="0.5" shininess="0.36" rgba="0.850000 0.850000 0.850000 1.000000"/>
    <mesh file="full/lift_high_500mm/lift_high_500mm.obj" scale="1.0 1.0 1.0"/>
    <material name="new_mat_color.019" specular="0.5" shininess="0.36" rgba="0.850000 0.850000 0.850000 1.000000"/>
    <mesh file="full/arm_mount/arm_mount.obj" scale="1.0 1.0 1.0"/>
    <material name="new_mat_color.020" specular="0.5" shininess="0.36" rgba="0.150000 0.150000 0.150000 1.000000"/>
    <mesh file="full/base/base_0.obj" scale="1.0 1.0 1.0"/>
    <mesh file="full/base/base_1.obj" scale="1.0 1.0 1.0"/>
    <material name="Black" specular="0.5" shininess="0.25" rgba="0.033102 0.033102 0.033102 1.000000"/>
    <material name="JointGrey" specular="0.5" shininess="0.25" rgba="0.278431 0.278431 0.278431 1.000000"/>
    <mesh file="full/shoulder/shoulder_0.obj" scale="1.0 1.0 1.0"/>
    <mesh file="full/shoulder/shoulder_1.obj" scale="1.0 1.0 1.0"/>
    <mesh file="full/shoulder/shoulder_2.obj" scale="1.0 1.0 1.0"/>
    <material name="Black.001" specular="0.5" shininess="0.25" rgba="0.033102 0.033102 0.033102 1.000000"/>
    <material name="JointGrey.001" specular="0.5" shininess="0.25" rgba="0.278431 0.278431 0.278431 1.000000"/>
    <material name="URBlue" specular="0.5" shininess="0.25" rgba="0.490196 0.678431 0.800000 1.000000"/>
    <mesh file="full/upperarm/upperarm_0.obj" scale="1.0 1.0 1.0"/>
    <mesh file="full/upperarm/upperarm_1.obj" scale="1.0 1.0 1.0"/>
    <mesh file="full/upperarm/upperarm_2.obj" scale="1.0 1.0 1.0"/>
    <mesh file="full/upperarm/upperarm_3.obj" scale="1.0 1.0 1.0"/>
    <material name="Black.002" specular="0.5" shininess="0.25" rgba="0.033102 0.033102 0.033102 1.000000"/>
    <material name="JointGrey.002" specular="0.5" shininess="0.25" rgba="0.278431 0.278431 0.278431 1.000000"/>
    <material name="LinkGrey" specular="0.5" shininess="0.25" rgba="0.820392 0.820392 0.820392 1.000000"/>
    <material name="URBlue.001" specular="0.5" shininess="0.25" rgba="0.490196 0.678431 0.800000 1.000000"/>
    <mesh file="full/forearm/forearm_0.obj" scale="1.0 1.0 1.0"/>
    <mesh file="full/forearm/forearm_1.obj" scale="1.0 1.0 1.0"/>
    <mesh file="full/forearm/forearm_2.obj" scale="1.0 1.0 1.0"/>
    <mesh file="full/forearm/forearm_3.obj" scale="1.0 1.0 1.0"/>
    <material name="Black.003" specular="0.5" shininess="0.25" rgba="0.033102 0.033102 0.033102 1.000000"/>
    <material name="JointGrey.003" specular="0.5" shininess="0.25" rgba="0.278431 0.278431 0.278431 1.000000"/>
    <material name="LinkGrey.001" specular="0.5" shininess="0.25" rgba="0.820392 0.820392 0.820392 1.000000"/>
    <material name="URBlue.002" specular="0.5" shininess="0.25" rgba="0.490196 0.678431 0.800000 1.000000"/>
    <mesh file="full/wrist1/wrist1_0.obj" scale="1.0 1.0 1.0"/>
    <mesh file="full/wrist1/wrist1_1.obj" scale="1.0 1.0 1.0"/>
    <mesh file="full/wrist1/wrist1_2.obj" scale="1.0 1.0 1.0"/>
    <material name="Black.004" specular="0.5" shininess="0.25" rgba="0.033102 0.033102 0.033102 1.000000"/>
    <material name="JointGrey.004" specular="0.5" shininess="0.25" rgba="0.278431 0.278431 0.278431 1.000000"/>
    <material name="URBlue.003" specular="0.5" shininess="0.25" rgba="0.490196 0.678431 0.800000 1.000000"/>
    <mesh file="full/wrist2/wrist2_0.obj" scale="1.0 1.0 1.0"/>
    <mesh file="full/wrist2/wrist2_1.obj" scale="1.0 1.0 1.0"/>
    <mesh file="full/wrist2/wrist2_2.obj" scale="1.0 1.0 1.0"/>
    <material name="Black.005" specular="0.5" shininess="0.25" rgba="0.033102 0.033102 0.033102 1.000000"/>
    <material name="JointGrey.005" specular="0.5" shininess="0.25" rgba="0.278431 0.278431 0.278431 1.000000"/>
    <material name="URBlue.004" specular="0.5" shininess="0.25" rgba="0.490196 0.678431 0.800000 1.000000"/>
    <mesh file="full/wrist3/wrist3.obj" scale="1.0 1.0 1.0"/>
    <material name="LinkGrey.002" specular="0.5" shininess="0.25" rgba="0.820392 0.820392 0.820392 1.000000"/>
    <mesh file="full/mtc_robot_side/mtc_robot_side.obj" scale="1.0 1.0 1.0"/>
    <material name="DEFAULT_MTL" specular="0.0" shininess="0.25" rgba="0.100000 0.100000 0.100000 1.000000"/>
    <mesh file="full/mtc_effector_side/mtc_effector_side.obj" scale="1.0 1.0 1.0"/>
    <material name="DEFAULT_MTL.002" specular="0.0" shininess="0.25" rgba="0.100000 0.100000 0.100000 1.000000"/>
    <mesh file="full/ich-005_realsense_cable_mount_corr/ich-005_realsense_cable_mount_corr.obj" scale="0.0254 0.0254 0.0254"/>
    <material name="new_mat_color.021" specular="0.5" shininess="0.36" rgba="0.100000 0.100000 0.100000 1.000000"/>
    <mesh file="full/robotiq_hande_cb_adapter/robotiq_hande_cb_adapter.obj" scale="1.0 1.0 1.0"/>
    <material name="DEFAULT_MTL.001" specular="0.0" shininess="0.25" rgba="0.800000 0.800000 0.800000 1.000000"/>
    <mesh file="full/hande/hande.obj" scale="0.001 0.001 0.001"/>
    <mesh file="decomposed/finger_v6/finger_v6/finger_v6.obj" scale="1.0 1.0 1.0"/>
    <mesh file="decomposed/finger_v6/finger_v6/finger_v6_collision_0.obj" scale="1.0 1.0 1.0"/>
    <mesh file="decomposed/finger_v6/finger_v6/finger_v6_collision_1.obj" scale="1.0 1.0 1.0"/>
    <mesh file="decomposed/finger_v6/finger_v6/finger_v6_collision_2.obj" scale="1.0 1.0 1.0"/>
    <mesh file="decomposed/finger_v6/finger_v6/finger_v6_collision_3.obj" scale="1.0 1.0 1.0"/>
    <mesh file="decomposed/finger_v6/finger_v6/finger_v6_collision_4.obj" scale="1.0 1.0 1.0"/>
    <mesh file="decomposed/finger_v6/finger_v6/finger_v6_collision_5.obj" scale="1.0 1.0 1.0"/>
    <mesh file="decomposed/finger_v6/finger_v6/finger_v6_collision_6.obj" scale="1.0 1.0 1.0"/>
    <mesh file="decomposed/finger_v6/finger_v6/finger_v6_collision_7.obj" scale="1.0 1.0 1.0"/>
    <mesh file="decomposed/finger_v6/finger_v6/finger_v6_collision_8.obj" scale="1.0 1.0 1.0"/>
    <mesh file="decomposed/finger_v6/finger_v6/finger_v6_collision_9.obj" scale="1.0 1.0 1.0"/>
    <mesh file="decomposed/finger_v6/finger_v6/finger_v6_collision_10.obj" scale="1.0 1.0 1.0"/>
    <mesh file="decomposed/finger_v6/finger_v6/finger_v6_collision_11.obj" scale="1.0 1.0 1.0"/>
    <mesh file="decomposed/finger_v6/finger_v6/finger_v6_collision_12.obj" scale="1.0 1.0 1.0"/>
    <mesh file="decomposed/finger_v6/finger_v6/finger_v6_collision_13.obj" scale="1.0 1.0 1.0"/>
    <mesh file="decomposed/finger_v6/finger_v6/finger_v6_collision_14.obj" scale="1.0 1.0 1.0"/>
    <mesh file="decomposed/finger_v6/finger_v6/finger_v6_collision_15.obj" scale="1.0 1.0 1.0"/>
    <mesh file="decomposed/finger_v6/finger_v6/finger_v6_collision_16.obj" scale="1.0 1.0 1.0"/>
    <mesh file="decomposed/finger_v6/finger_v6/finger_v6_collision_17.obj" scale="1.0 1.0 1.0"/>
    <material name="new_mat_color.022" specular="0.5" shininess="0.36" rgba="0.200000 0.200000 0.200000 1.000000"/>
    <mesh file="decomposed/finger_1/finger_1/finger_1.obj" scale="0.001 0.001 0.001"/>
    <mesh file="decomposed/finger_1/finger_1/finger_1_collision_0.obj" scale="0.001 0.001 0.001"/>
    <mesh file="decomposed/finger_1/finger_1/finger_1_collision_1.obj" scale="0.001 0.001 0.001"/>
    <mesh file="decomposed/finger_1/finger_1/finger_1_collision_2.obj" scale="0.001 0.001 0.001"/>
    <mesh file="decomposed/finger_1/finger_1/finger_1_collision_3.obj" scale="0.001 0.001 0.001"/>
    <mesh file="decomposed/finger_1/finger_1/finger_1_collision_4.obj" scale="0.001 0.001 0.001"/>
    <mesh file="decomposed/finger_1/finger_1/finger_1_collision_5.obj" scale="0.001 0.001 0.001"/>
    <mesh file="decomposed/finger_1/finger_1/finger_1_collision_6.obj" scale="0.001 0.001 0.001"/>
    <mesh file="decomposed/finger_1/finger_1/finger_1_collision_7.obj" scale="0.001 0.001 0.001"/>
    <mesh file="decomposed/finger_1/finger_1/finger_1_collision_8.obj" scale="0.001 0.001 0.001"/>
    <mesh file="decomposed/finger_1/finger_1/finger_1_collision_9.obj" scale="0.001 0.001 0.001"/>
    <mesh file="decomposed/finger_1/finger_1/finger_1_collision_10.obj" scale="0.001 0.001 0.001"/>
    <mesh file="decomposed/finger_1/finger_1/finger_1_collision_11.obj" scale="0.001 0.001 0.001"/>
    <mesh file="decomposed/finger_1/finger_1/finger_1_collision_12.obj" scale="0.001 0.001 0.001"/>
    <mesh file="decomposed/finger_1/finger_1/finger_1_collision_13.obj" scale="0.001 0.001 0.001"/>
    <mesh file="decomposed/finger_1/finger_1/finger_1_collision_14.obj" scale="0.001 0.001 0.001"/>
    <mesh file="decomposed/finger_1/finger_1/finger_1_collision_15.obj" scale="0.001 0.001 0.001"/>
    <mesh file="decomposed/finger_1/finger_1/finger_1_collision_16.obj" scale="0.001 0.001 0.001"/>
    <material name="new_mat_color.023" specular="0.5" shininess="0.36" rgba="0.200000 0.200000 0.200000 1.000000"/>
    <mesh file="mecanum_wheel_22.stl" scale="0.001 0.001 0.001"/>
  </asset>
  <worldbody>
    <geom name="floor" type="plane" size="5 5 0.1" pos="0 0 0" rgba="0.8 0.8 0.8 1"/>
    <body name="base_link">
      <inertial pos="0.0151044 0.00165701 0.0943591" quat="0.717959 -0.0265943 -0.0142385 0.695432" mass="199.343" diaginertia="11.7956 10.8921 8.18537"/>
      <freejoint name="floating_base_joint"/>
      <include file="wheels.xml"/>
      <body name="left_ewellix_lift_higher_link" pos="0 0.201 0.61">
        <inertial pos="-0.00482427 -0.148669 0.00425385" quat="0.722569 0.691108 -0.0112101 -0.0117204" mass="9.32488" diaginertia="0.405037 0.30676 0.130026"/>
        <joint name="left_ewellix_lift_lower_to_higher" pos="0 0 0" axis="0 0 1" type="slide" range="0 0.5" actuatorfrcrange="-1000 1000"/>
        <body name="left_ewellix_lift_middle_link" pos="0 0 -0.0303">
          <inertial pos="0 0 0" mass="5.4116" diaginertia="0.11963 0.11963 0.0330997"/>
          <joint name="left_middle_mimic_higher" pos="0 0 0" axis="0 0 -1" type="slide" range="0 0.25" actuatorfrcrange="-1000 1000"/>
          <geom material="new_mat_color.018" mesh="lift_mid_500mm" class="visual" pos="" quat=""/>
          <geom mesh="lift_mid_500mm" class="collision" pos="" quat=""/>
          <site name="left_ewellix_lift_middle_link" pos="0 0 0" quat="1.0 0 0 0"/>
        </body>
        <body name="left_ur_arm_shoulder_link" pos="0.0126802 0.124615 0.463459" quat="0.353086 -0.134633 0.350748 0.856843">
          <inertial pos="0 -0.00193 -0.02561" quat="0.560239 0.250606 -0.316559 0.72327" mass="3.761" diaginertia="0.00703079 0.0070003 0.00602478"/>
          <joint name="left_ur_arm_shoulder_pan_joint" pos="0 0 0" axis="0 0 1" range="-6.28319 6.28319" actuatorfrcrange="-150 150"/>
          <body name="left_ur_arm_upper_arm_link" pos="0.000226782 0 0" quat="0.707115 0.707098 -9.55133e-07 -9.55157e-07">
            <inertial pos="-0.2125 0 0.11336" quat="0.500275 0.499641 0.500368 0.499716" mass="8.058" diaginertia="0.333881 0.332472 0.0150588"/>
            <joint name="left_ur_arm_shoulder_lift_joint" pos="0 0 0" axis="0 0 1" range="-6.28319 6.28319" actuatorfrcrange="-150 150"/>
            <body name="left_ur_arm_forearm_link" pos="-0.425505 0 0" quat="1 2.07226e-05 -0.000262987 -7.61405e-08">
              <inertial pos="-0.2422 0 0.0265" quat="0.501301 0.498381 0.510711 0.489375" mass="2.846" diaginertia="0.0787927 0.0785102 0.00397103"/>
              <joint name="left_ur_arm_elbow_joint" pos="0 0 0" axis="0 0 1" range="-3.14159 3.14159" actuatorfrcrange="-150 150"/>
              <body name="left_ur_arm_wrist_1_link" pos="-0.392582 -4.63122e-05 0.133721" quat="1 0.000173166 0.000544517 1.77883e-06">
                <inertial pos="0 -0.01634 -0.0018" quat="0.960609 0.277707 0.00515042 -0.00913626" mass="1.37" diaginertia="0.00165502 0.00142363 0.00119868"/>
                <joint name="left_ur_arm_wrist_1_joint" pos="0 0 0" axis="0 0 1" range="-6.28319 6.28319" actuatorfrcrange="-28 28"/>
                <body name="left_ur_arm_wrist_2_link" pos="1.36989e-05 -0.0999777 8.48591e-05" quat="0.707407 0.706807 -4.64337e-08 -4.64731e-08">
                  <inertial pos="0 0.01634 -0.0018" quat="0.996652 -0.0779336 -0.00684629 -0.0237381" mass="1.3" diaginertia="0.00135637 0.00128607 0.00095814"/>
                  <joint name="left_ur_arm_wrist_2_joint" pos="0 0 0" axis="0 0 1" range="-6.28319 6.28319" actuatorfrcrange="-28 28"/>
                  <body name="left_ur_arm_wrist_3_link" pos="0.000106733 0.0996158 1.94962e-05" quat="-0.707176 0.707038 1.93623e-08 -1.93661e-08">
                    <inertial pos="0.000839754 -0.00316796 0.065463" quat="0.724907 0.688778 0.0074684 0.00631936" mass="1.31087" diaginertia="0.00765268 0.0049038 0.00405629"/>
                    <joint name="left_ur_arm_wrist_3_joint" pos="0 0 0" axis="0 0 1" range="-6.28319 6.28319" actuatorfrcrange="-28 28"/>
                    <body name="left_finger_1_link" pos="0.025 0 0.146" quat="0 0 0 -1">
                      <inertial pos="-0.02262 0.00759 0.00738" quat="0.871952 -0.0369732 0.211073 0.440205" mass="0.03804" diaginertia="1.22763e-05 1.22763e-05 1.22763e-05"/>
                      <joint name="left_finger_1_joint" pos="0 0 0" axis="1 0 0" type="slide" range="0 0.025" actuatorfrcrange="-130 130"/>
                      <geom material="new_mat_color.023" mesh="finger_1" class="visual" pos="" quat=""/>
                      <geom mesh="finger_1_collision_0" rgba="0.6192047630789531 0.1798918860970241 0.46550270600231103 1" class="collision" pos="" quat=""/>
                      <geom mesh="finger_1_collision_1" rgba="0.12548365616742707 0.4169879407812068 0.8585330674162476 1" class="collision" pos="" quat=""/>
                      <geom mesh="finger_1_collision_2" rgba="0.806695151239711 0.6061582569055793 0.5573540208917612 1" class="collision" pos="" quat=""/>
                      <geom mesh="finger_1_collision_3" rgba="0.9021169227140297 0.34797352451207053 0.153678531670561 1" class="collision" pos="" quat=""/>
                      <geom mesh="finger_1_collision_4" rgba="0.5747037224061728 0.5988889964500744 0.1780531864767687 1" class="collision" pos="" quat=""/>
                      <geom mesh="finger_1_collision_5" rgba="0.2844263535166681 0.513154014665106 0.3793950563639128 1" class="collision" pos="" quat=""/>
                      <geom mesh="finger_1_collision_6" rgba="0.7726362864107219 0.6557060287327873 0.9502766382495667 1" class="collision" pos="" quat=""/>
                      <geom mesh="finger_1_collision_7" rgba="0.6891504131999012 0.7058251723550518 0.16484593727198882 1" class="collision" pos="" quat=""/>
                      <geom mesh="finger_1_collision_8" rgba="0.5208349110326382 0.09604916736057512 0.41612276471266785 1" class="collision" pos="" quat=""/>
                      <geom mesh="finger_1_collision_9" rgba="0.1575959363400693 0.4535280718052722 0.6933041383431137 1" class="collision" pos="" quat=""/>
                      <geom mesh="finger_1_collision_10" rgba="0.34607649156470666 0.43208351741759055 0.530630566672801 1" class="collision" pos="" quat=""/>
                      <geom mesh="finger_1_collision_11" rgba="0.9031459156325523 0.16706224274308235 0.7091216457391037 1" class="collision" pos="" quat=""/>
                      <geom mesh="finger_1_collision_12" rgba="0.3524576776707232 0.7130403627684129 0.7643501848831463 1" class="collision" pos="" quat=""/>
                      <geom mesh="finger_1_collision_13" rgba="0.9685724052951808 0.7685867408407155 0.7322061148634995 1" class="collision" pos="" quat=""/>
                      <geom mesh="finger_1_collision_14" rgba="0.5418333356031758 0.15615553983515318 0.9739771886676672 1" class="collision" pos="" quat=""/>
                      <geom mesh="finger_1_collision_15" rgba="0.9191326130380535 0.003683522075901835 0.612881567843329 1" class="collision" pos="" quat=""/>
                      <geom mesh="finger_1_collision_16" rgba="0.9315763514513771 0.9653204450174085 0.7169485104081637 1" class="collision" pos="" quat=""/>
                      <site name="left_finger_1_link" pos="0 0 0" quat="1.0 0 0 0"/>
                    </body>
                    <body name="left_finger_2_link" pos="-0.025 0 0.146" quat="-1 0 0 0">
                      <inertial pos="0.02262 -0.00759 0.00738" quat="0.871952 0.0369732 -0.211073 0.440205" mass="0.03804" diaginertia="1.22763e-05 1.22763e-05 1.22763e-05"/>
                      <joint name="left_finger_2_joint" pos="0 0 0" axis="1 0 0" type="slide" range="0 0.025" actuatorfrcrange="-130 130"/>
                      <geom material="new_mat_color.023" mesh="finger_1" class="visual" pos="" quat=""/>
                      <geom mesh="finger_1_collision_0" rgba="0.6192047630789531 0.1798918860970241 0.46550270600231103 1" class="collision" pos="" quat=""/>
                      <geom mesh="finger_1_collision_1" rgba="0.12548365616742707 0.4169879407812068 0.8585330674162476 1" class="collision" pos="" quat=""/>
                      <geom mesh="finger_1_collision_2" rgba="0.806695151239711 0.6061582569055793 0.5573540208917612 1" class="collision" pos="" quat=""/>
                      <geom mesh="finger_1_collision_3" rgba="0.9021169227140297 0.34797352451207053 0.153678531670561 1" class="collision" pos="" quat=""/>
                      <geom mesh="finger_1_collision_4" rgba="0.5747037224061728 0.5988889964500744 0.1780531864767687 1" class="collision" pos="" quat=""/>
                      <geom mesh="finger_1_collision_5" rgba="0.2844263535166681 0.513154014665106 0.3793950563639128 1" class="collision" pos="" quat=""/>
                      <geom mesh="finger_1_collision_6" rgba="0.7726362864107219 0.6557060287327873 0.9502766382495667 1" class="collision" pos="" quat=""/>
                      <geom mesh="finger_1_collision_7" rgba="0.6891504131999012 0.7058251723550518 0.16484593727198882 1" class="collision" pos="" quat=""/>
                      <geom mesh="finger_1_collision_8" rgba="0.5208349110326382 0.09604916736057512 0.41612276471266785 1" class="collision" pos="" quat=""/>
                      <geom mesh="finger_1_collision_9" rgba="0.1575959363400693 0.4535280718052722 0.6933041383431137 1" class="collision" pos="" quat=""/>
                      <geom mesh="finger_1_collision_10" rgba="0.34607649156470666 0.43208351741759055 0.530630566672801 1" class="collision" pos="" quat=""/>
                      <geom mesh="finger_1_collision_11" rgba="0.9031459156325523 0.16706224274308235 0.7091216457391037 1" class="collision" pos="" quat=""/>
                      <geom mesh="finger_1_collision_12" rgba="0.3524576776707232 0.7130403627684129 0.7643501848831463 1" class="collision" pos="" quat=""/>
                      <geom mesh="finger_1_collision_13" rgba="0.9685724052951808 0.7685867408407155 0.7322061148634995 1" class="collision" pos="" quat=""/>
                      <geom mesh="finger_1_collision_14" rgba="0.5418333356031758 0.15615553983515318 0.9739771886676672 1" class="collision" pos="" quat=""/>
                      <geom mesh="finger_1_collision_15" rgba="0.9191326130380535 0.003683522075901835 0.612881567843329 1" class="collision" pos="" quat=""/>
                      <geom mesh="finger_1_collision_16" rgba="0.9315763514513771 0.9653204450174085 0.7169485104081637 1" class="collision" pos="" quat=""/>
                      <site name="left_finger_2_link" pos="0 0 0" quat="1.0 0 0 0"/>
                    </body>
                    <geom material="LinkGrey.002" mesh="wrist3" class="visual" pos="0 0 -0.0989" quat="0.707107 0.707107 0 0"/>
                    <geom mesh="wrist3" class="collision" pos="0 0 -0.0989" quat="0.707107 0.707107 0 0"/>
                    <geom material="DEFAULT_MTL" mesh="mtc_robot_side" class="visual" pos="" quat="0 0 0 1"/>
                    <geom mesh="mtc_robot_side" class="collision" pos="" quat="0 0 0 1"/>
                    <geom material="DEFAULT_MTL.002" mesh="mtc_effector_side" class="visual" pos="0 0 0.009" quat="0 0 0 1"/>
                    <geom mesh="mtc_effector_side" class="collision" pos="0 0 0.009" quat="0 0 0 1"/>
                    <geom material="new_mat_color.021" mesh="ich-005_realsense_cable_mount_corr" class="visual" pos="0 0 0.033" quat="-0.707107 0 0 0.707107"/>
                    <geom mesh="ich-005_realsense_cable_mount_corr" class="collision" pos="0 0 0.033" quat="-0.707107 0 0 0.707107"/>
                    <geom material="DEFAULT_MTL.001" mesh="robotiq_hande_cb_adapter" class="visual" pos="0 0 0.036" quat="-1 0 0 0"/>
                    <geom mesh="robotiq_hande_cb_adapter" class="collision" pos="0 0 0.036" quat="-1 0 0 0"/>
                    <geom mesh="hande" class="visual" pos="0 0 0.047" quat="-1 0 0 0"/>
                    <geom mesh="hande" class="collision" pos="0 0 0.047" quat="-1 0 0 0"/>
                    <geom size="0.012525 0.045 0.0125" pos="0.000178732 0.0759414 0.0578834" quat="-0.53321 0.471099 0.468121 0.524037" type="box" class="collision"/>
                    <geom size="0.012525 0.045 0.0125" pos="0.000178732 0.0759414 0.0578834" quat="-0.53321 0.471099 0.468121 0.524037" type="box" class="visual"/>
                    <site name="left_ur_arm_wrist_3_link" pos="0 0 0" quat="1.0 0 0 0"/>
                    <site name="left_ur_arm_ft_frame" pos="0 0 0" quat="0 1.0 0 0"/>
                    <site name="left_ur_arm_flange" pos="0 0 0" quat="-0.5000000000000001 0.5 0.5000000000000001 0.49999999999999994"/>
                    <site name="left_ur_arm_tool0" pos="0 0 0" quat="1.0 0 0 0"/>
                    <site name="left_mtc_robot_side" pos="0 0 0" quat="0 0 0 1.0"/>
                    <site name="left_mtc_effector_side" pos="0 0 0.009" quat="0 0 0 1.0"/>
                    <site name="left_ur_realsense_mount" pos="0 0 0.033" quat="0.7071067811865475 0 0 -0.7071067811865476"/>
                    <site name="left_wrist_mounted_camera_bottom_screw_frame" pos="0.00011461581058039112 0.06477723247500103 0.04588481485344156" quat="0.5332101511675295 -0.4710992667519285 -0.46812105206923166 -0.5240373041752767"/>
                    <site name="left_wrist_mounted_camera_link" pos="0.01767710423050336 0.07606221192742246 0.05767753461007523" quat="0.5332101511675295 -0.4710992667519285 -0.46812105206923166 -0.5240373041752767"/>
                    <site name="left_wrist_mounted_camera_depth_frame" pos="0.01767710423050336 0.07606221192742246 0.05767753461007523" quat="0.5332101511675295 -0.4710992667519285 -0.46812105206923166 -0.5240373041752767"/>
                    <site name="left_wrist_mounted_camera_depth_optical_frame" pos="0.01767710423050336 0.07606221192742246 0.05767753461007523" quat="-0.00309731615477802 0.006075530837474827 -0.05901356826082302 0.9982338870819831"/>
                    <site name="left_wrist_mounted_camera_infra1_frame" pos="0.01767710423050336 0.07606221192742246 0.05767753461007523" quat="0.5332101511675295 -0.4710992667519285 -0.46812105206923166 -0.5240373041752767"/>
                    <site name="left_wrist_mounted_camera_infra1_optical_frame" pos="0.01767710423050336 0.07606221192742246 0.05767753461007523" quat="-0.00309731615477802 0.006075530837474827 -0.05901356826082302 0.9982338870819831"/>
                    <site name="left_wrist_mounted_camera_infra2_frame" pos="-0.03231824522526468 0.07571717345757206 0.05826573631864059" quat="0.5332101511675295 -0.4710992667519285 -0.46812105206923166 -0.5240373041752767"/>
                    <site name="left_wrist_mounted_camera_infra2_optical_frame" pos="-0.03231824522526468 0.07571717345757206 0.05826573631864059" quat="-0.00309731615477802 0.006075530837474827 -0.05901356826082302 0.9982338870819831"/>
                    <site name="left_wrist_mounted_camera_color_frame" pos="0.03267570906723376 0.07616572346837758 0.05750107409750563" quat="0.5332101511675295 -0.4710992667519285 -0.46812105206923166 -0.5240373041752767"/>
                    <site name="left_wrist_mounted_camera_color_optical_frame" pos="0.03267570906723376 0.07616572346837758 0.05750107409750563" quat="-0.00309731615477802 0.006075530837474827 -0.05901356826082302 0.9982338870819831"/>
                    <site name="left_robotiq_hande_cb_adapter" pos="0 0 0.036" quat="1.0 0 0 0"/>
                    <site name="left_gripper_base_link" pos="0 0 0.047" quat="1.0 0 0 0"/>
                    <site name="left_gripper_palm_link" pos="0 0 0.1458" quat="1.0 0 0 0"/>
                    <camera name="left_wrist_mounted_camera" fovy="58" mode="fixed" resolution="640 480" pos="0.03267570906723376 0.07616572346837758 0.05750107409750563" quat="-0.006075530837474827 -0.00309731615477802 0.9982338870819831 0.05901356826082302"/>
                  </body>
                  <geom mesh="wrist2_0" material="Black.005" class="visual" pos="0 0 -0.0997" quat="1 0 0 0"/>
                  <geom mesh="wrist2_1" material="URBlue.004" class="visual" pos="0 0 -0.0997" quat="1 0 0 0"/>
                  <geom mesh="wrist2_2" material="JointGrey.005" class="visual" pos="0 0 -0.0997" quat="1 0 0 0"/>
                  <geom mesh="wrist2_0" class="collision" pos="0 0 -0.0997" quat="1 0 0 0"/>
                  <geom mesh="wrist2_1" class="collision" pos="0 0 -0.0997" quat="1 0 0 0"/>
                  <geom mesh="wrist2_2" class="collision" pos="0 0 -0.0997" quat="1 0 0 0"/>
                  <site name="left_ur_arm_wrist_2_link" pos="0 0 0" quat="1.0 0 0 0"/>
                </body>
                <geom mesh="wrist1_0" material="Black.004" class="visual" pos="0 0 -0.127" quat="0.707107 0.707107 0 0"/>
                <geom mesh="wrist1_1" material="URBlue.003" class="visual" pos="0 0 -0.127" quat="0.707107 0.707107 0 0"/>
                <geom mesh="wrist1_2" material="JointGrey.004" class="visual" pos="0 0 -0.127" quat="0.707107 0.707107 0 0"/>
                <geom mesh="wrist1_0" class="collision" pos="0 0 -0.127" quat="0.707107 0.707107 0 0"/>
                <geom mesh="wrist1_1" class="collision" pos="0 0 -0.127" quat="0.707107 0.707107 0 0"/>
                <geom mesh="wrist1_2" class="collision" pos="0 0 -0.127" quat="0.707107 0.707107 0 0"/>
                <site name="left_ur_arm_wrist_1_link" pos="0 0 0" quat="1.0 0 0 0"/>
              </body>
              <geom mesh="forearm_0" material="URBlue.002" class="visual" pos="0 0 0.007" quat="0.5 0.5 -0.5 -0.5"/>
              <geom mesh="forearm_1" material="LinkGrey.001" class="visual" pos="0 0 0.007" quat="0.5 0.5 -0.5 -0.5"/>
              <geom mesh="forearm_2" material="Black.003" class="visual" pos="0 0 0.007" quat="0.5 0.5 -0.5 -0.5"/>
              <geom mesh="forearm_3" material="JointGrey.003" class="visual" pos="0 0 0.007" quat="0.5 0.5 -0.5 -0.5"/>
              <geom mesh="forearm_0" class="collision" pos="0 0 0.007" quat="0.5 0.5 -0.5 -0.5"/>
              <geom mesh="forearm_1" class="collision" pos="0 0 0.007" quat="0.5 0.5 -0.5 -0.5"/>
              <geom mesh="forearm_2" class="collision" pos="0 0 0.007" quat="0.5 0.5 -0.5 -0.5"/>
              <geom mesh="forearm_3" class="collision" pos="0 0 0.007" quat="0.5 0.5 -0.5 -0.5"/>
              <site name="left_ur_arm_forearm_link" pos="0 0 0" quat="1.0 0 0 0"/>
            </body>
            <geom mesh="upperarm_0" material="LinkGrey" class="visual" pos="0 0 0.138" quat="0.5 0.5 -0.5 -0.5"/>
            <geom mesh="upperarm_1" material="Black.002" class="visual" pos="0 0 0.138" quat="0.5 0.5 -0.5 -0.5"/>
            <geom mesh="upperarm_2" material="JointGrey.002" class="visual" pos="0 0 0.138" quat="0.5 0.5 -0.5 -0.5"/>
            <geom mesh="upperarm_3" material="URBlue.001" class="visual" pos="0 0 0.138" quat="0.5 0.5 -0.5 -0.5"/>
            <geom mesh="upperarm_0" class="collision" pos="0 0 0.138" quat="0.5 0.5 -0.5 -0.5"/>
            <geom mesh="upperarm_1" class="collision" pos="0 0 0.138" quat="0.5 0.5 -0.5 -0.5"/>
            <geom mesh="upperarm_2" class="collision" pos="0 0 0.138" quat="0.5 0.5 -0.5 -0.5"/>
            <geom mesh="upperarm_3" class="collision" pos="0 0 0.138" quat="0.5 0.5 -0.5 -0.5"/>
            <site name="left_ur_arm_upper_arm_link" pos="0 0 0" quat="1.0 0 0 0"/>
          </body>
          <geom mesh="shoulder_0" material="URBlue" class="visual" pos="" quat="0 0 0 1"/>
          <geom mesh="shoulder_1" material="Black.001" class="visual" pos="" quat="0 0 0 1"/>
          <geom mesh="shoulder_2" material="JointGrey.001" class="visual" pos="" quat="0 0 0 1"/>
          <geom mesh="shoulder_0" class="collision" pos="" quat="0 0 0 1"/>
          <geom mesh="shoulder_1" class="collision" pos="" quat="0 0 0 1"/>
          <geom mesh="shoulder_2" class="collision" pos="" quat="0 0 0 1"/>
          <site name="left_ur_arm_shoulder_link" pos="0 0 0" quat="1.0 0 0 0"/>
        </body>
        <geom material="new_mat_color.019" mesh="lift_high_500mm" class="visual" pos="" quat=""/>
        <geom mesh="lift_high_500mm" class="collision" pos="" quat=""/>
        <geom material="new_mat_color.020" mesh="arm_mount" class="visual" pos="0 0 0.245" quat="1 0 0 0"/>
        <geom mesh="arm_mount" class="collision" pos="0 0 0.245" quat="1 0 0 0"/>
        <geom mesh="base_0" material="Black" class="visual" pos="0.00991665 0.0112464 0.346581" quat="-0.856843 0.350748 0.134633 0.353087"/>
        <geom mesh="base_1" material="JointGrey" class="visual" pos="0.00991665 0.0112464 0.346581" quat="-0.856843 0.350748 0.134633 0.353087"/>
        <geom mesh="base_0" class="collision" pos="0.00991665 0.0112464 0.346581" quat="-0.856843 0.350748 0.134633 0.353087"/>
        <geom mesh="base_1" class="collision" pos="0.00991665 0.0112464 0.346581" quat="-0.856843 0.350748 0.134633 0.353087"/>
        <site name="left_ewellix_lift_higher_link" pos="0 0 0" quat="1.0 0 0 0"/>
        <site name="left_ewellix_lift_tip_link" pos="0 0 0.245" quat="1.0 0 0 0"/>
        <site name="left_arm_mount_plate" pos="0 0 0.245" quat="1.0 0 0 0"/>
        <site name="left_arm_cal_link" pos="0.00807 -0.00363 0.25519" quat="0.9999207717653594 0.00766532164373513 0.009738255189799393 -0.002204409699753492"/>
        <site name="left_arm_mount_plate_2" pos="0.009916652070851292 0.011246430320808633 0.34658085838878716" quat="0.9267397267637125 -0.37557127925555456 0.009840565722468038 0.001690059918407977"/>
        <site name="left_ur_arm_base_link" pos="0.009916652070851292 0.011246430320808633 0.34658085838878716" quat="0.8568426234525752 -0.3507484393703761 -0.1346334089839429 -0.353086527779688"/>
        <site name="left_ur_arm_base_link_inertia" pos="0.009916652070851292 0.011246430320808633 0.34658085838878716" quat="0.35308652777968813 -0.13463340898394294 0.35074843937037603 0.8568426234525752"/>
        <site name="left_ur_arm_base" pos="0.009916652070851292 0.011246430320808633 0.34658085838878716" quat="0.35308652777968813 -0.13463340898394294 0.35074843937037603 0.8568426234525752"/>
      </body>
      <body name="right_ewellix_lift_higher_link" pos="0 -0.201 0.61">
        <inertial pos="0.00637989 -0.148041 0.0049205" quat="0.725038 0.688372 0.0148258 0.0156155" mass="9.32488" diaginertia="0.403015 0.304783 0.129982"/>
        <joint name="right_ewellix_lift_lower_to_higher" pos="0 0 0" axis="0 0 1" type="slide" range="0 0.5" actuatorfrcrange="-1000 1000"/>
        <body name="right_ewellix_lift_middle_link" pos="0 0 -0.0303">
          <inertial pos="0 0 0" mass="5.4116" diaginertia="0.11963 0.11963 0.0330997"/>
          <joint name="right_middle_mimic_higher" pos="0 0 0" axis="0 0 -1" type="slide" range="0 0.25" actuatorfrcrange="-1000 1000"/>
          <geom material="new_mat_color.018" mesh="lift_mid_500mm" class="visual" pos="" quat=""/>
          <geom mesh="lift_mid_500mm" class="collision" pos="" quat=""/>
          <site name="right_ewellix_lift_middle_link" pos="0 0 0" quat="1.0 0 0 0"/>
        </body>
        <body name="right_ur_arm_shoulder_link" pos="0.0147855 -0.128643 0.461404" quat="0.857772 0.353915 -0.131976 0.348645">
          <inertial pos="0 -0.00193 -0.02561" quat="0.560239 0.250606 -0.316559 0.72327" mass="3.761" diaginertia="0.00703079 0.0070003 0.00602478"/>
          <joint name="right_ur_arm_shoulder_pan_joint" pos="0 0 0" axis="0 0 1" range="-6.28319 6.28319" actuatorfrcrange="-150 150"/>
          <body name="right_ur_arm_upper_arm_link" pos="7.08681e-05 0 0" quat="0.707305 0.706908 1.4235e-06 1.4243e-06">
            <inertial pos="-0.2125 0 0.11336" quat="0.500275 0.499641 0.500368 0.499716" mass="8.058" diaginertia="0.333881 0.332472 0.0150588"/>
            <joint name="right_ur_arm_shoulder_lift_joint" pos="0 0 0" axis="0 0 1" range="-6.28319 6.28319" actuatorfrcrange="-150 150"/>
            <body name="right_ur_arm_forearm_link" pos="-0.425304 0 0" quat="1 9.70614e-05 0.000269354 4.69205e-07">
              <inertial pos="-0.2422 0 0.0265" quat="0.501301 0.498381 0.510711 0.489375" mass="2.846" diaginertia="0.0787927 0.0785102 0.00397103"/>
              <joint name="right_ur_arm_elbow_joint" pos="0 0 0" axis="0 0 1" range="-3.14159 3.14159" actuatorfrcrange="-150 150"/>
              <body name="right_ur_arm_wrist_1_link" pos="-0.392184 8.85386e-05 0.134008" quat="1 -0.000330347 0.000508859 -1.44648e-06">
                <inertial pos="0 -0.01634 -0.0018" quat="0.960609 0.277707 0.00515042 -0.00913626" mass="1.37" diaginertia="0.00165502 0.00142363 0.00119868"/>
                <joint name="right_ur_arm_wrist_1_joint" pos="0 0 0" axis="0 0 1" range="-6.28319 6.28319" actuatorfrcrange="-28 28"/>
                <body name="right_ur_arm_wrist_2_link" pos="3.88504e-05 -0.0998073 8.22332e-05" quat="0.707398 0.706815 2.04332e-07 2.045e-07">
                  <inertial pos="0 0.01634 -0.0018" quat="0.996652 -0.0779336 -0.00684629 -0.0237381" mass="1.3" diaginertia="0.00135637 0.00128607 0.00095814"/>
                  <joint name="right_ur_arm_wrist_2_joint" pos="0 0 0" axis="0 0 1" range="-6.28319 6.28319" actuatorfrcrange="-28 28"/>
                  <body name="right_ur_arm_wrist_3_link" pos="7.98405e-05 0.0996341 1.16486e-05" quat="-0.707148 0.707065 4.07248e-09 -4.07295e-09">
                    <inertial pos="0.000681263 -0.00313372 0.0653098" quat="0.720299 0.693617 0.00574545 0.00567072" mass="1.31087" diaginertia="0.00764365 0.00489151 0.00404757"/>
                    <joint name="right_ur_arm_wrist_3_joint" pos="0 0 0" axis="0 0 1" range="-6.28319 6.28319" actuatorfrcrange="-28 28"/>
                    <body name="right_finger_1_link" pos="0.011014 -0.00325 0.1475" quat="-1 0 0 0">
                      <inertial pos="0 0 0" quat="0.501643 0.0653163 0.068404 0.859889" mass="0.0500198" diaginertia="6.28755e-05 6.17965e-05 5.99521e-06"/>
                      <joint name="right_finger_1_joint" pos="0 0 0" axis="1 0 0" type="slide" range="0 0.025" actuatorfrcrange="-130 130"/>
                      <geom material="new_mat_color.022" mesh="finger_v6" class="visual" pos="" quat=""/>
                      <geom mesh="finger_v6_collision_0" rgba="0.5234787124115464 0.41081422588158845 0.9772960368633239 1" class="collision" pos="" quat=""/>
                      <geom mesh="finger_v6_collision_1" rgba="0.18157662711368172 0.1733071153986091 0.8328158508229857 1" class="collision" pos="" quat=""/>
                      <geom mesh="finger_v6_collision_2" rgba="0.5416299692200852 0.05188420119321002 0.12450801247270538 1" class="collision" pos="" quat=""/>
                      <geom mesh="finger_v6_collision_3" rgba="0.5339534327460655 0.10779019102095289 0.40099025118259013 1" class="collision" pos="" quat=""/>
                      <geom mesh="finger_v6_collision_4" rgba="0.0711652230370613 0.27835815727386626 0.4437183919178439 1" class="collision" pos="" quat=""/>
                      <geom mesh="finger_v6_collision_5" rgba="0.36161011205624827 0.1339459159032632 0.446760896066979 1" class="collision" pos="" quat=""/>
                      <geom mesh="finger_v6_collision_6" rgba="0.3237961180987353 0.12736550229585775 0.18580111887540907 1" class="collision" pos="" quat=""/>
                      <geom mesh="finger_v6_collision_7" rgba="0.4872109694757948 0.49583247241464945 0.13982589836575843 1" class="collision" pos="" quat=""/>
                      <geom mesh="finger_v6_collision_8" rgba="0.5566209531593418 0.861794758982558 0.7015675407700404 1" class="collision" pos="" quat=""/>
                      <geom mesh="finger_v6_collision_9" rgba="0.48243944803022654 0.18704978273970274 0.3515491775879691 1" class="collision" pos="" quat=""/>
                      <geom mesh="finger_v6_collision_10" rgba="0.1404724458979929 0.3493794794313255 0.4622955408828682 1" class="collision" pos="" quat=""/>
                      <geom mesh="finger_v6_collision_11" rgba="0.11435585539212689 0.5636077929026019 0.9606955557581901 1" class="collision" pos="" quat=""/>
                      <geom mesh="finger_v6_collision_12" rgba="0.9327747714789169 0.9662687303311027 0.5300565324365947 1" class="collision" pos="" quat=""/>
                      <geom mesh="finger_v6_collision_13" rgba="0.5451012608864526 0.9574963327135549 0.36301995590017744 1" class="collision" pos="" quat=""/>
                      <geom mesh="finger_v6_collision_14" rgba="0.023037941333429957 0.01325771674776699 0.19286103976682767 1" class="collision" pos="" quat=""/>
                      <geom mesh="finger_v6_collision_15" rgba="0.685180237919834 0.6043892444457369 0.7844234961172964 1" class="collision" pos="" quat=""/>
                      <geom mesh="finger_v6_collision_16" rgba="0.12453720659187617 0.48592985281517176 0.5343094422137674 1" class="collision" pos="" quat=""/>
                      <geom mesh="finger_v6_collision_17" rgba="0.09542146048223266 0.17776043727401902 0.12369964856910065 1" class="collision" pos="" quat=""/>
                      <site name="right_finger_1_link" pos="0 0 0" quat="1.0 0 0 0"/>
                    </body>
                    <body name="right_finger_2_link" pos="-0.011014 0.00325 0.1475" quat="0 0 0 -1">
                      <inertial pos="0 0 0" quat="0.501643 0.0653163 0.068404 0.859889" mass="0.0500198" diaginertia="6.28755e-05 6.17965e-05 5.99521e-06"/>
                      <joint name="right_finger_2_joint" pos="0 0 0" axis="1 0 0" type="slide" range="0 0.025" actuatorfrcrange="-130 130"/>
                      <geom material="new_mat_color.022" mesh="finger_v6" class="visual" pos="" quat=""/>
                      <geom mesh="finger_v6_collision_0" rgba="0.5234787124115464 0.41081422588158845 0.9772960368633239 1" class="collision" pos="" quat=""/>
                      <geom mesh="finger_v6_collision_1" rgba="0.18157662711368172 0.1733071153986091 0.8328158508229857 1" class="collision" pos="" quat=""/>
                      <geom mesh="finger_v6_collision_2" rgba="0.5416299692200852 0.05188420119321002 0.12450801247270538 1" class="collision" pos="" quat=""/>
                      <geom mesh="finger_v6_collision_3" rgba="0.5339534327460655 0.10779019102095289 0.40099025118259013 1" class="collision" pos="" quat=""/>
                      <geom mesh="finger_v6_collision_4" rgba="0.0711652230370613 0.27835815727386626 0.4437183919178439 1" class="collision" pos="" quat=""/>
                      <geom mesh="finger_v6_collision_5" rgba="0.36161011205624827 0.1339459159032632 0.446760896066979 1" class="collision" pos="" quat=""/>
                      <geom mesh="finger_v6_collision_6" rgba="0.3237961180987353 0.12736550229585775 0.18580111887540907 1" class="collision" pos="" quat=""/>
                      <geom mesh="finger_v6_collision_7" rgba="0.4872109694757948 0.49583247241464945 0.13982589836575843 1" class="collision" pos="" quat=""/>
                      <geom mesh="finger_v6_collision_8" rgba="0.5566209531593418 0.861794758982558 0.7015675407700404 1" class="collision" pos="" quat=""/>
                      <geom mesh="finger_v6_collision_9" rgba="0.48243944803022654 0.18704978273970274 0.3515491775879691 1" class="collision" pos="" quat=""/>
                      <geom mesh="finger_v6_collision_10" rgba="0.1404724458979929 0.3493794794313255 0.4622955408828682 1" class="collision" pos="" quat=""/>
                      <geom mesh="finger_v6_collision_11" rgba="0.11435585539212689 0.5636077929026019 0.9606955557581901 1" class="collision" pos="" quat=""/>
                      <geom mesh="finger_v6_collision_12" rgba="0.9327747714789169 0.9662687303311027 0.5300565324365947 1" class="collision" pos="" quat=""/>
                      <geom mesh="finger_v6_collision_13" rgba="0.5451012608864526 0.9574963327135549 0.36301995590017744 1" class="collision" pos="" quat=""/>
                      <geom mesh="finger_v6_collision_14" rgba="0.023037941333429957 0.01325771674776699 0.19286103976682767 1" class="collision" pos="" quat=""/>
                      <geom mesh="finger_v6_collision_15" rgba="0.685180237919834 0.6043892444457369 0.7844234961172964 1" class="collision" pos="" quat=""/>
                      <geom mesh="finger_v6_collision_16" rgba="0.12453720659187617 0.48592985281517176 0.5343094422137674 1" class="collision" pos="" quat=""/>
                      <geom mesh="finger_v6_collision_17" rgba="0.09542146048223266 0.17776043727401902 0.12369964856910065 1" class="collision" pos="" quat=""/>
                      <site name="right_finger_2_link" pos="0 0 0" quat="1.0 0 0 0"/>
                    </body>
                    <geom material="LinkGrey.002" mesh="wrist3" class="visual" pos="0 0 -0.0989" quat="0.707107 0.707107 0 0"/>
                    <geom mesh="wrist3" class="collision" pos="0 0 -0.0989" quat="0.707107 0.707107 0 0"/>
                    <geom material="DEFAULT_MTL" mesh="mtc_robot_side" class="visual" pos="" quat="0 0 0 1"/>
                    <geom mesh="mtc_robot_side" class="collision" pos="" quat="0 0 0 1"/>
                    <geom material="DEFAULT_MTL.002" mesh="mtc_effector_side" class="visual" pos="0 0 0.009" quat="0 0 0 1"/>
                    <geom mesh="mtc_effector_side" class="collision" pos="0 0 0.009" quat="0 0 0 1"/>
                    <geom material="new_mat_color.021" mesh="ich-005_realsense_cable_mount_corr" class="visual" pos="0 0 0.033" quat="-0.707107 0 0 0.707107"/>
                    <geom mesh="ich-005_realsense_cable_mount_corr" class="collision" pos="0 0 0.033" quat="-0.707107 0 0 0.707107"/>
                    <geom material="DEFAULT_MTL.001" mesh="robotiq_hande_cb_adapter" class="visual" pos="0 0 0.036" quat="-1 0 0 0"/>
                    <geom mesh="robotiq_hande_cb_adapter" class="collision" pos="0 0 0.036" quat="-1 0 0 0"/>
                    <geom mesh="hande" class="visual" pos="0 0 0.047" quat="-1 0 0 0"/>
                    <geom mesh="hande" class="collision" pos="0 0 0.047" quat="-1 0 0 0"/>
                    <geom size="0.012525 0.045 0.0125" pos="-0.00270487 0.0729183 0.0570653" quat="-0.53474 0.464316 0.473489 0.523709" type="box" class="collision"/>
                    <geom size="0.012525 0.045 0.0125" pos="-0.00270487 0.0729183 0.0570653" quat="-0.53474 0.464316 0.473489 0.523709" type="box" class="visual"/>
                    <site name="right_ur_arm_wrist_3_link" pos="0 0 0" quat="1.0 0 0 0"/>
                    <site name="right_ur_arm_ft_frame" pos="0 0 0" quat="0 1.0 0 0"/>
                    <site name="right_ur_arm_flange" pos="0 0 0" quat="-0.5000000000000001 0.5 0.5000000000000001 0.49999999999999994"/>
                    <site name="right_ur_arm_tool0" pos="0 0 0" quat="1.0 0 0 0"/>
                    <site name="right_mtc_robot_side" pos="0 0 0" quat="0 0 0 1.0"/>
                    <site name="right_mtc_effector_side" pos="0 0 0.009" quat="0 0 0 1.0"/>
                    <site name="right_ur_realsense_mount" pos="0 0 0.033" quat="0.7071067811865475 0 0 -0.7071067811865476"/>
                    <site name="right_wrist_mounted_camera_bottom_screw_frame" pos="-0.0024867707148071697 0.06178805647696173 0.04503697006925041" quat="0.5347404914295344 -0.46431583558336753 -0.4734889852715583 -0.5237094542575391"/>
                    <site name="right_wrist_mounted_camera_link" pos="0.014791524429828526 0.07327316271090978 0.05705415991088087" quat="0.5347404914295344 -0.46431583558336753 -0.4734889852715583 -0.5237094542575391"/>
                    <site name="right_wrist_mounted_camera_depth_frame" pos="0.014791524429828526 0.07327316271090978 0.05705415991088087" quat="0.5347404914295344 -0.46431583558336753 -0.4734889852715583 -0.5237094542575391"/>
                    <site name="right_wrist_mounted_camera_depth_optical_frame" pos="0.014791524429828526 0.07327316271090978 0.05705415991088087" quat="-0.010102093430093039 0.0009289437419023142 -0.06032256241607385 0.9981273832709996"/>
                    <site name="right_wrist_mounted_camera_infra1_frame" pos="0.014791524429828526 0.07327316271090978 0.05705415991088087" quat="0.5347404914295344 -0.46431583558336753 -0.4734889852715583 -0.5237094542575391"/>
                    <site name="right_wrist_mounted_camera_infra1_optical_frame" pos="0.014791524429828526 0.07327316271090978 0.05705415991088087" quat="-0.010102093430093039 0.0009289437419023142 -0.06032256241607385 0.9981273832709996"/>
                    <site name="right_wrist_mounted_camera_infra2_frame" pos="-0.03519818404735689 0.07225924147613079 0.05708594191336498" quat="0.5347404914295344 -0.46431583558336753 -0.4734889852715583 -0.5237094542575391"/>
                    <site name="right_wrist_mounted_camera_infra2_optical_frame" pos="-0.03519818404735689 0.07225924147613079 0.05708594191336498" quat="-0.010102093430093039 0.0009289437419023142 -0.06032256241607385 0.9981273832709996"/>
                    <site name="right_wrist_mounted_camera_color_frame" pos="0.029788436972984143 0.07357733908134348 0.05704462531013564" quat="0.5347404914295344 -0.46431583558336753 -0.4734889852715583 -0.5237094542575391"/>
                    <site name="right_wrist_mounted_camera_color_optical_frame" pos="0.029788436972984143 0.07357733908134348 0.05704462531013564" quat="-0.010102093430093039 0.0009289437419023142 -0.06032256241607385 0.9981273832709996"/>
                    <site name="right_robotiq_hande_cb_adapter" pos="0 0 0.036" quat="1.0 0 0 0"/>
                    <site name="right_gripper_base_link" pos="0 0 0.047" quat="1.0 0 0 0"/>
                    <site name="right_gripper_palm_link" pos="0 0 0.1458" quat="1.0 0 0 0"/>
                    <camera name="right_wrist_mounted_camera" fovy="58" mode="fixed" resolution="640 480" pos="0.029788436972984143 0.07357733908134348 0.05704462531013564" quat="-0.0009289437419023142 -0.010102093430093039 0.9981273832709996 0.06032256241607385"/>
                  </body>
                  <geom mesh="wrist2_0" material="Black.005" class="visual" pos="0 0 -0.0997" quat="1 0 0 0"/>
                  <geom mesh="wrist2_1" material="URBlue.004" class="visual" pos="0 0 -0.0997" quat="1 0 0 0"/>
                  <geom mesh="wrist2_2" material="JointGrey.005" class="visual" pos="0 0 -0.0997" quat="1 0 0 0"/>
                  <geom mesh="wrist2_0" class="collision" pos="0 0 -0.0997" quat="1 0 0 0"/>
                  <geom mesh="wrist2_1" class="collision" pos="0 0 -0.0997" quat="1 0 0 0"/>
                  <geom mesh="wrist2_2" class="collision" pos="0 0 -0.0997" quat="1 0 0 0"/>
                  <site name="right_ur_arm_wrist_2_link" pos="0 0 0" quat="1.0 0 0 0"/>
                </body>
                <geom mesh="wrist1_0" material="Black.004" class="visual" pos="0 0 -0.127" quat="0.707107 0.707107 0 0"/>
                <geom mesh="wrist1_1" material="URBlue.003" class="visual" pos="0 0 -0.127" quat="0.707107 0.707107 0 0"/>
                <geom mesh="wrist1_2" material="JointGrey.004" class="visual" pos="0 0 -0.127" quat="0.707107 0.707107 0 0"/>
                <geom mesh="wrist1_0" class="collision" pos="0 0 -0.127" quat="0.707107 0.707107 0 0"/>
                <geom mesh="wrist1_1" class="collision" pos="0 0 -0.127" quat="0.707107 0.707107 0 0"/>
                <geom mesh="wrist1_2" class="collision" pos="0 0 -0.127" quat="0.707107 0.707107 0 0"/>
                <site name="right_ur_arm_wrist_1_link" pos="0 0 0" quat="1.0 0 0 0"/>
              </body>
              <geom mesh="forearm_0" material="URBlue.002" class="visual" pos="0 0 0.007" quat="0.5 0.5 -0.5 -0.5"/>
              <geom mesh="forearm_1" material="LinkGrey.001" class="visual" pos="0 0 0.007" quat="0.5 0.5 -0.5 -0.5"/>
              <geom mesh="forearm_2" material="Black.003" class="visual" pos="0 0 0.007" quat="0.5 0.5 -0.5 -0.5"/>
              <geom mesh="forearm_3" material="JointGrey.003" class="visual" pos="0 0 0.007" quat="0.5 0.5 -0.5 -0.5"/>
              <geom mesh="forearm_0" class="collision" pos="0 0 0.007" quat="0.5 0.5 -0.5 -0.5"/>
              <geom mesh="forearm_1" class="collision" pos="0 0 0.007" quat="0.5 0.5 -0.5 -0.5"/>
              <geom mesh="forearm_2" class="collision" pos="0 0 0.007" quat="0.5 0.5 -0.5 -0.5"/>
              <geom mesh="forearm_3" class="collision" pos="0 0 0.007" quat="0.5 0.5 -0.5 -0.5"/>
              <site name="right_ur_arm_forearm_link" pos="0 0 0" quat="1.0 0 0 0"/>
            </body>
            <geom mesh="upperarm_0" material="LinkGrey" class="visual" pos="0 0 0.138" quat="0.5 0.5 -0.5 -0.5"/>
            <geom mesh="upperarm_1" material="Black.002" class="visual" pos="0 0 0.138" quat="0.5 0.5 -0.5 -0.5"/>
            <geom mesh="upperarm_2" material="JointGrey.002" class="visual" pos="0 0 0.138" quat="0.5 0.5 -0.5 -0.5"/>
            <geom mesh="upperarm_3" material="URBlue.001" class="visual" pos="0 0 0.138" quat="0.5 0.5 -0.5 -0.5"/>
            <geom mesh="upperarm_0" class="collision" pos="0 0 0.138" quat="0.5 0.5 -0.5 -0.5"/>
            <geom mesh="upperarm_1" class="collision" pos="0 0 0.138" quat="0.5 0.5 -0.5 -0.5"/>
            <geom mesh="upperarm_2" class="collision" pos="0 0 0.138" quat="0.5 0.5 -0.5 -0.5"/>
            <geom mesh="upperarm_3" class="collision" pos="0 0 0.138" quat="0.5 0.5 -0.5 -0.5"/>
            <site name="right_ur_arm_upper_arm_link" pos="0 0 0" quat="1.0 0 0 0"/>
          </body>
          <geom mesh="shoulder_0" material="URBlue" class="visual" pos="" quat="0 0 0 1"/>
          <geom mesh="shoulder_1" material="Black.001" class="visual" pos="" quat="0 0 0 1"/>
          <geom mesh="shoulder_2" material="JointGrey.001" class="visual" pos="" quat="0 0 0 1"/>
          <geom mesh="shoulder_0" class="collision" pos="" quat="0 0 0 1"/>
          <geom mesh="shoulder_1" class="collision" pos="" quat="0 0 0 1"/>
          <geom mesh="shoulder_2" class="collision" pos="" quat="0 0 0 1"/>
          <site name="right_ur_arm_shoulder_link" pos="0 0 0" quat="1.0 0 0 0"/>
        </body>
        <geom material="new_mat_color.019" mesh="lift_high_500mm" class="visual" pos="" quat=""/>
        <geom mesh="lift_high_500mm" class="collision" pos="" quat=""/>
        <geom material="new_mat_color.020" mesh="arm_mount" class="visual" pos="0 0 0.245" quat="0 0 0 1"/>
        <geom mesh="arm_mount" class="collision" pos="0 0 0.245" quat="0 0 0 1"/>
        <geom mesh="base_0" material="Black" class="visual" pos="0.0114708 -0.0148729 0.345116" quat="-0.348645 -0.131976 -0.353915 0.857772"/>
        <geom mesh="base_1" material="JointGrey" class="visual" pos="0.0114708 -0.0148729 0.345116" quat="-0.348645 -0.131976 -0.353915 0.857772"/>
        <geom mesh="base_0" class="collision" pos="0.0114708 -0.0148729 0.345116" quat="-0.348645 -0.131976 -0.353915 0.857772"/>
        <geom mesh="base_1" class="collision" pos="0.0114708 -0.0148729 0.345116" quat="-0.348645 -0.131976 -0.353915 0.857772"/>
        <site name="right_ewellix_lift_higher_link" pos="0 0 0" quat="1.0 0 0 0"/>
        <site name="right_ewellix_lift_tip_link" pos="0 0 0.245" quat="1.0 0 0 0"/>
        <site name="right_arm_mount_plate" pos="0 0 0.245" quat="0 0 0 1.0"/>
        <site name="right_arm_cal_link" pos="0.00878 0.0003899999999999989 0.25381" quat="0.0005120290270251525 0.014832547761266168 0.005580531822850569 0.9998742876070768"/>
        <site name="right_arm_mount_plate_2" pos="0.011470773314534262 -0.014872936032459481 0.34511613244814854" quat="0.9258989664768731 0.3774795851834155 0.013507542266097355 -0.006149223426120727"/>
        <site name="right_ur_arm_base_link" pos="0.011470773314534262 -0.014872936032459481 0.34511613244814854" quat="-0.34864505285042696 -0.13197584147156124 -0.35391477532901505 0.8577723102284248"/>
        <site name="right_ur_arm_base_link_inertia" pos="0.011470773314534262 -0.014872936032459481 0.34511613244814854" quat="0.857772310228425 0.35391477532901494 -0.1319758414715612 0.3486450528504269"/>
        <site name="right_ur_arm_base" pos="0.011470773314534262 -0.014872936032459481 0.34511613244814854" quat="0.857772310228425 0.35391477532901494 -0.1319758414715612 0.3486450528504269"/>
      </body>
      <geom material="new_mat_color" mesh="body" class="visual" pos="" quat=""/>
      <geom mesh="body" class="collision" pos="" quat=""/>
      <geom material="new_mat_color.001" mesh="side-cover" class="visual" pos="" quat=""/>
      <geom mesh="side-cover" class="collision" pos="" quat=""/>
      <geom material="new_mat_color.001" mesh="side-cover" class="visual" pos="0 0 0" quat="0 0 0 1"/>
      <geom mesh="side-cover" class="collision" pos="0 0 0" quat="0 0 0 1"/>
      <geom material="new_mat_color.002" mesh="end-cover" class="visual" pos="" quat=""/>
      <geom mesh="end-cover" class="collision" pos="" quat=""/>
      <geom material="new_mat_color.002" mesh="end-cover" class="visual" pos="0 0 0" quat="0 0 0 1"/>
      <geom mesh="end-cover" class="collision" pos="0 0 0" quat="0 0 0 1"/>
      <geom material="new_mat_color.003" mesh="lights" class="visual" pos="" quat=""/>
      <geom mesh="lights" class="collision" pos="" quat=""/>
      <geom material="new_mat_color.003" mesh="lights" class="visual" pos="0 0 0" quat="0 0 0 1"/>
      <geom mesh="lights" class="collision" pos="0 0 0" quat="0 0 0 1"/>
      <geom material="new_mat_color.004" mesh="axle" class="visual" pos="0 0 0.05" quat="0.707107 0 0.707107 0"/>
      <geom mesh="axle" class="collision" pos="0 0 0.05" quat="0.707107 0 0.707107 0"/>
      <geom material="new_mat_color.005" mesh="top" class="visual" pos="" quat=""/>
      <geom mesh="top" class="collision" pos="" quat=""/>
      <geom material="new_mat_color.006" mesh="rocker" class="visual" pos="0.319 0 0.05" quat="0.5 0.5 0.5 0.5"/>
      <geom mesh="rocker" class="collision" pos="0.319 0 0.05" quat="0.5 0.5 0.5 0.5"/>
      <geom material="new_mat_color.006" mesh="rocker" class="visual" pos="-0.319 0 0.05" quat="0.5 0.5 0.5 0.5"/>
      <geom mesh="rocker" class="collision" pos="-0.319 0 0.05" quat="0.5 0.5 0.5 0.5"/>
      <geom material="new_mat_color.008" mesh="lift_rails" class="visual" pos="0 0 0.28" quat="1 0 0 0"/>
      <geom mesh="lift_rails" class="collision" pos="0 0 0.28" quat="1 0 0 0"/>
      <geom material="new_mat_color.009" mesh="shelf" class="visual" pos="0 0 0.28" quat="1 0 0 0"/>
      <geom mesh="shelf" class="collision" pos="0 0 0.28" quat="1 0 0 0"/>
      <geom material="new_mat_color.009" mesh="shelf" class="visual" pos="0 0 0.28" quat="0 0 0 1"/>
      <geom mesh="shelf" class="collision" pos="0 0 0.28" quat="0 0 0 1"/>
      <geom material="new_mat_color.010" mesh="monitor_hinge_base" class="visual" pos="-0.4 0 0.52635" quat="1 0 0 0"/>
      <geom mesh="monitor_hinge_base" class="collision" pos="-0.4 0 0.52635" quat="1 0 0 0"/>
      <geom material="new_mat_color.011" mesh="monitor_hinge_top" class="visual" pos="-0.4 0 0.52635" quat="0.932327 0 0.361615 0"/>
      <geom mesh="monitor_hinge_top" class="collision" pos="-0.4 0 0.52635" quat="0.932327 0 0.361615 0"/>
      <geom material="new_mat_color.012" mesh="monitor" class="visual" pos="-0.422796 0.18 0.560706" quat="0.932327 0 0.361615 0"/>
      <geom mesh="monitor" class="collision" pos="-0.422796 0.18 0.560706" quat="0.932327 0 0.361615 0"/>
      <geom material="new_mat_color.012" mesh="monitor" class="visual" pos="-0.422796 -0.18 0.560706" quat="0.932327 0 0.361615 0"/>
      <geom mesh="monitor" class="collision" pos="-0.422796 -0.18 0.560706" quat="0.932327 0 0.361615 0"/>
      <geom material="new_mat_color.013" mesh="scu" class="visual" pos="-0.18187 0 0.28" quat="1 0 0 0"/>
      <geom mesh="scu" class="collision" pos="-0.18187 0 0.28" quat="1 0 0 0"/>
      <geom material="new_mat_color.013" mesh="scu" class="visual" pos="0.18187 0 0.28" quat="0 0 0 1"/>
      <geom mesh="scu" class="collision" pos="0.18187 0 0.28" quat="0 0 0 1"/>
      <geom material="new_mat_color.014" mesh="autec_receiver" class="visual" pos="-0.26 -0.29909 0.28" quat="1 0 0 0"/>
      <geom mesh="autec_receiver" class="collision" pos="-0.26 -0.29909 0.28" quat="1 0 0 0"/>
      <geom material="new_mat_color.015" mesh="wifi_antenna" class="visual" pos="-0.086 -0.384 0.5" quat="1 0 0 0"/>
      <geom mesh="wifi_antenna" class="collision" pos="-0.086 -0.384 0.5" quat="1 0 0 0"/>
      <geom material="new_mat_color.015" mesh="wifi_antenna" class="visual" pos="-0.086 0.384 0.5" quat="1 0 0 0"/>
      <geom mesh="wifi_antenna" class="collision" pos="-0.086 0.384 0.5" quat="1 0 0 0"/>
      <geom material="new_mat_color.016" mesh="autec_antenna" class="visual" pos="0.0845 -0.384 0.5" quat="1 0 0 0"/>
      <geom mesh="autec_antenna" class="collision" pos="0.0845 -0.384 0.5" quat="1 0 0 0"/>
      <geom material="new_mat_color.017" mesh="lift_low_500mm" class="visual" pos="0 0.201 0.5732" quat=""/>
      <geom mesh="lift_low_500mm" class="collision" pos="0 0.201 0.5732" quat=""/>
      <geom material="new_mat_color.017" mesh="lift_low_500mm" class="visual" pos="0 -0.201 0.5732" quat=""/>
      <geom mesh="lift_low_500mm" class="collision" pos="0 -0.201 0.5732" quat=""/>
      <geom size="0.2465 0.2465 0.0275" pos="0 0 0.2475" quat="0.92388 0 0 0.382683" type="box" class="collision"/>
      <geom size="0.2465 0.2465 0.0275" pos="0 0 0.2475" quat="0.92388 0 0 0.382683" type="box" rgba="0.8 0.8 0.8 1" class="visual"/>
      <geom size="0.1 0.1 0.0075" pos="0 0.201 0.3275" type="box" class="collision"/>
      <geom size="0.1 0.1 0.0075" pos="0 0.201 0.3275" type="box" class="visual"/>
      <geom size="0.1 0.1 0.0075" pos="0 -0.201 0.3275" type="box" class="collision"/>
      <geom size="0.1 0.1 0.0075" pos="0 -0.201 0.3275" type="box" class="visual"/>
      <site name="base_link" pos="0 0 0" quat="1.0 0 0 0"/>
      <site name="chassis_link" pos="0 0 0" quat="1.0 0 0 0"/>
      <site name="left_side_cover_link" pos="0 0 0" quat="1.0 0 0 0"/>
      <site name="right_side_cover_link" pos="0 0 0" quat="1.0 0 0 0"/>
      <site name="front_cover_link" pos="0 0 0" quat="1.0 0 0 0"/>
      <site name="rear_cover_link" pos="0 0 0" quat="1.0 0 0 0"/>
      <site name="front_lights_link" pos="0 0 0" quat="1.0 0 0 0"/>
      <site name="rear_lights_link" pos="0 0 0" quat="1.0 0 0 0"/>
      <site name="axle_link" pos="0 0 0.05" quat="1.0 0 0 0"/>
      <site name="riser_link" pos="0 0 0.22" quat="1.0 0 0 0"/>
      <site name="top_link" pos="0 0 0" quat="1.0 0 0 0"/>
      <site name="front_rocker_link" pos="0.319 0 0.05" quat="1.0 0 0 0"/>
      <site name="rear_rocker_link" pos="-0.319 0 0.05" quat="1.0 0 0 0"/>
      <site name="imu_0_link" pos="0.2085 -0.2902 0.1681" quat="1.0 0 0 0"/>
      <site name="lidar2d_0_laser" pos="0.4 0 0.25" quat="1.0 0 0 0"/>
      <site name="default_mount" pos="0 0 0.28" quat="1.0 0 0 0"/>
      <site name="lift_rails" pos="0 0 0.28" quat="1.0 0 0 0"/>
      <site name="rear_shelf" pos="0 0 0.28" quat="1.0 0 0 0"/>
      <site name="front_shelf" pos="0 0 0.28" quat="0 0 0 1.0"/>
      <site name="monitor_hinge_base" pos="-0.4 0 0.52635" quat="1.0 0 0 0"/>
      <site name="monitor_hinge_top" pos="-0.4 0 0.52635" quat="0.9323273456060344 0 0.361615431964962 0"/>
      <site name="left_monitor" pos="-0.4227958632329021 0.18 0.5607062020524217" quat="0.9323273456060344 0 0.361615431964962 0"/>
      <site name="right_monitor" pos="-0.4227958632329021 -0.18 0.5607062020524217" quat="0.9323273456060344 0 0.361615431964962 0"/>
      <site name="rear_scu" pos="-0.18187 0 0.28" quat="1.0 0 0 0"/>
      <site name="front_scu" pos="0.18187 0 0.28" quat="0 0 0 1.0"/>
      <site name="autec_receiver" pos="-0.26 -0.29909 0.28" quat="1.0 0 0 0"/>
      <site name="right_wifi_antenna" pos="-0.086 -0.384 0.5" quat="1.0 0 0 0"/>
      <site name="left_wifi_antenna" pos="-0.086 0.384 0.5" quat="1.0 0 0 0"/>
      <site name="autec_antenna" pos="0.0845 -0.384 0.5" quat="1.0 0 0 0"/>
      <site name="left_ewellix_mount_flange_link" pos="0 0.201 0.32" quat="1.0 0 0 0"/>
      <site name="right_ewellix_mount_flange_link" pos="0 -0.201 0.32" quat="1.0 0 0 0"/>
      <site name="left_ewellix_lift_lower_link" pos="0 0.201 0.5731999999999999" quat="1.0 0 0 0"/>
      <site name="right_ewellix_lift_lower_link" pos="0 -0.201 0.5731999999999999" quat="1.0 0 0 0"/>
      <body name="lidar2d_0_laser_lidar_body" pos="0.4 0 0.25" quat="0.6606256905723392 0.6606256905723392 -0.25213824968818177 -0.25213824968818177">
        <replicate site="lidar2d_0_laser" count="46" sep="-" offset="0 0 0" euler="0 0.1 0">
          <site name="lidar2d_0" pos="0.0 0.0 0.0" quat="0.0 0.0 0.0 1.0"/>
        </replicate>
      </body>
    </body>
  </worldbody>
  <option integrator="implicitfast"/>
  <default>
    <default class="phoebe">
      <material specular="0.5" shininess="0.25"/>
      <joint axis="0 1 0" range="-6.28319 6.28319" armature="0.1"/>
      <position ctrlrange="-6.2831 6.2831"/>
      <general biastype="affine" ctrlrange="-6.2831 6.2831"/>
      <default class="size4">
        <joint damping="10"/>
        <general forcerange="-330 330" gainprm="100000" biasprm="0 -100000 -10000"/>
      </default>
      <default class="size3">
        <joint damping="5"/>
        <general forcerange="-150 150" gainprm="40000" biasprm="0 -40000 -4000"/>
        <default class="size3_limited">
          <joint range="-3.1415 3.1415"/>
          <general ctrlrange="-3.1415 3.1415"/>
        </default>
      </default>
      <default class="size2">
        <joint damping="2"/>
        <general forcerange="-56 56" gainprm="10000" biasprm="0 -10000 -1000"/>
      </default>
      <default class="hande">
        <joint damping="2"/>
        <general forcerange="-50 50" ctrlrange="0.0 0.025" gainprm="1000" biasprm="0 -1000 -100"/>
      </default>
      <default class="visual">
        <geom group="2" type="mesh" contype="0" conaffinity="0"/>
      </default>
      <default class="collision">
        <geom group="3" type="mesh"/>
      </default>
    </default>
  </default>
  <actuator>
    <position joint="left_ewellix_lift_lower_to_higher" name="left_ewellix_lift_lower_to_higher" kp="75000" dampratio="1.0" ctrlrange="0.0 0.7"/>
    <position joint="right_ewellix_lift_lower_to_higher" name="right_ewellix_lift_lower_to_higher" kp="75000" dampratio="1.0" ctrlrange="0.0 0.7"/>
    <position joint="left_finger_1_joint" name="left_finger_1_joint" kp="10000" dampratio="100.0" ctrlrange="0.0 0.025" forcerange="-50 50"/>
    <position joint="right_finger_1_joint" name="right_finger_1_joint" kp="10000" dampratio="100.0" ctrlrange="0.0 0.025" forcerange="-50 50"/>
    <general class="size4" name="left_ur_arm_shoulder_pan_joint" joint="left_ur_arm_shoulder_pan_joint"/>
    <general class="size4" name="left_ur_arm_shoulder_lift_joint" joint="left_ur_arm_shoulder_lift_joint"/>
    <general class="size3_limited" name="left_ur_arm_elbow_joint" joint="left_ur_arm_elbow_joint"/>
    <general class="size2" name="left_ur_arm_wrist_1_joint" joint="left_ur_arm_wrist_1_joint"/>
    <general class="size2" name="left_ur_arm_wrist_2_joint" joint="left_ur_arm_wrist_2_joint"/>
    <general class="size2" name="left_ur_arm_wrist_3_joint" joint="left_ur_arm_wrist_3_joint"/>
    <general class="size4" name="right_ur_arm_shoulder_pan_joint" joint="right_ur_arm_shoulder_pan_joint"/>
    <general class="size4" name="right_ur_arm_shoulder_lift_joint" joint="right_ur_arm_shoulder_lift_joint"/>
    <general class="size3_limited" name="right_ur_arm_elbow_joint" joint="right_ur_arm_elbow_joint"/>
    <general class="size2" name="right_ur_arm_wrist_1_joint" joint="right_ur_arm_wrist_1_joint"/>
    <general class="size2" name="right_ur_arm_wrist_2_joint" joint="right_ur_arm_wrist_2_joint"/>
    <general class="size2" name="right_ur_arm_wrist_3_joint" joint="right_ur_arm_wrist_3_joint"/>
    <velocity name="front_right_wheel_joint" joint="front_right_wheel_joint" ctrlrange="-15 15" kv="50"/>
    <velocity name="front_left_wheel_joint" joint="front_left_wheel_joint" ctrlrange="-15 15" kv="50"/>
    <velocity name="rear_right_wheel_joint" joint="rear_right_wheel_joint" ctrlrange="-15 15" kv="50"/>
    <velocity name="rear_left_wheel_joint" joint="rear_left_wheel_joint" ctrlrange="-15 15" kv="50"/>
  </actuator>
  <contact>
    <exclude body1="base_link" body2="left_ewellix_lift_higher_link"/>
    <exclude body1="base_link" body2="left_ewellix_lift_middle_link"/>
    <exclude body1="base_link" body2="right_ewellix_lift_higher_link"/>
    <exclude body1="base_link" body2="right_ewellix_lift_middle_link"/>
    <exclude body1="base_link" body2="rear_left_wheel_link"/>
    <exclude body1="base_link" body2="rear_left_wheel_roller_0_link"/>
    <exclude body1="base_link" body2="rear_left_wheel_roller_1_link"/>
    <exclude body1="base_link" body2="rear_left_wheel_roller_2_link"/>
    <exclude body1="base_link" body2="rear_left_wheel_roller_3_link"/>
    <exclude body1="base_link" body2="rear_left_wheel_roller_4_link"/>
    <exclude body1="base_link" body2="rear_left_wheel_roller_5_link"/>
    <exclude body1="base_link" body2="rear_left_wheel_roller_6_link"/>
    <exclude body1="base_link" body2="rear_left_wheel_roller_7_link"/>
    <exclude body1="base_link" body2="rear_right_wheel_link"/>
    <exclude body1="base_link" body2="rear_right_wheel_roller_0_link"/>
    <exclude body1="base_link" body2="rear_right_wheel_roller_1_link"/>
    <exclude body1="base_link" body2="rear_right_wheel_roller_2_link"/>
    <exclude body1="base_link" body2="rear_right_wheel_roller_3_link"/>
    <exclude body1="base_link" body2="rear_right_wheel_roller_4_link"/>
    <exclude body1="base_link" body2="rear_right_wheel_roller_5_link"/>
    <exclude body1="base_link" body2="rear_right_wheel_roller_6_link"/>
    <exclude body1="base_link" body2="rear_right_wheel_roller_7_link"/>
    <exclude body1="base_link" body2="front_left_wheel_link"/>
    <exclude body1="base_link" body2="front_left_wheel_roller_0_link"/>
    <exclude body1="base_link" body2="front_left_wheel_roller_1_link"/>
    <exclude body1="base_link" body2="front_left_wheel_roller_2_link"/>
    <exclude body1="base_link" body2="front_left_wheel_roller_3_link"/>
    <exclude body1="base_link" body2="front_left_wheel_roller_4_link"/>
    <exclude body1="base_link" body2="front_left_wheel_roller_5_link"/>
    <exclude body1="base_link" body2="front_left_wheel_roller_6_link"/>
    <exclude body1="base_link" body2="front_left_wheel_roller_7_link"/>
    <exclude body1="base_link" body2="front_right_wheel_link"/>
    <exclude body1="base_link" body2="front_right_wheel_roller_0_link"/>
    <exclude body1="base_link" body2="front_right_wheel_roller_1_link"/>
    <exclude body1="base_link" body2="front_right_wheel_roller_2_link"/>
    <exclude body1="base_link" body2="front_right_wheel_roller_3_link"/>
    <exclude body1="base_link" body2="front_right_wheel_roller_4_link"/>
    <exclude body1="base_link" body2="front_right_wheel_roller_5_link"/>
    <exclude body1="base_link" body2="front_right_wheel_roller_6_link"/>
    <exclude body1="base_link" body2="front_right_wheel_roller_7_link"/>
    <pair geom1="mecanum_wheel1" geom2="floor" condim="3" friction="0.5 0.5 0.005 0.0001 0.0001" solimp="0.95 0.99 0.001 0.1 6"/>
    <pair geom1="mecanum_wheel2" geom2="floor" condim="3" friction="0.5 0.5 0.005 0.0001 0.0001" solimp="0.95 0.99 0.001 0.1 6"/>
    <pair geom1="mecanum_wheel3" geom2="floor" condim="3" friction="0.5 0.5 0.005 0.0001 0.0001" solimp="0.95 0.99 0.001 0.1 6"/>
    <pair geom1="mecanum_wheel4" geom2="floor" condim="3" friction="0.5 0.5 0.005 0.0001 0.0001" solimp="0.95 0.99 0.001 0.1 6"/>
    <pair geom1="mecanum_wheel5" geom2="floor" condim="3" friction="0.5 0.5 0.005 0.0001 0.0001" solimp="0.95 0.99 0.001 0.1 6"/>
    <pair geom1="mecanum_wheel6" geom2="floor" condim="3" friction="0.5 0.5 0.005 0.0001 0.0001" solimp="0.95 0.99 0.001 0.1 6"/>
    <pair geom1="mecanum_wheel7" geom2="floor" condim="3" friction="0.5 0.5 0.005 0.0001 0.0001" solimp="0.95 0.99 0.001 0.1 6"/>
    <pair geom1="mecanum_wheel8" geom2="floor" condim="3" friction="0.5 0.5 0.005 0.0001 0.0001" solimp="0.95 0.99 0.001 0.1 6"/>
    <pair geom1="mecanum_wheel9" geom2="floor" condim="3" friction="0.5 0.5 0.005 0.0001 0.0001" solimp="0.95 0.99 0.001 0.1 6"/>
    <pair geom1="mecanum_wheel10" geom2="floor" condim="3" friction="0.5 0.5 0.005 0.0001 0.0001" solimp="0.95 0.99 0.001 0.1 6"/>
    <pair geom1="mecanum_wheel11" geom2="floor" condim="3" friction="0.5 0.5 0.005 0.0001 0.0001" solimp="0.95 0.99 0.001 0.1 6"/>
    <pair geom1="mecanum_wheel12" geom2="floor" condim="3" friction="0.5 0.5 0.005 0.0001 0.0001" solimp="0.95 0.99 0.001 0.1 6"/>
    <pair geom1="mecanum_wheel13" geom2="floor" condim="3" friction="0.5 0.5 0.005 0.0001 0.0001" solimp="0.95 0.99 0.001 0.1 6"/>
    <pair geom1="mecanum_wheel14" geom2="floor" condim="3" friction="0.5 0.5 0.005 0.0001 0.0001" solimp="0.95 0.99 0.001 0.1 6"/>
    <pair geom1="mecanum_wheel15" geom2="floor" condim="3" friction="0.5 0.5 0.005 0.0001 0.0001" solimp="0.95 0.99 0.001 0.1 6"/>
    <pair geom1="mecanum_wheel16" geom2="floor" condim="3" friction="0.5 0.5 0.005 0.0001 0.0001" solimp="0.95 0.99 0.001 0.1 6"/>
    <pair geom1="mecanum_wheel17" geom2="floor" condim="3" friction="0.5 0.5 0.005 0.0001 0.0001" solimp="0.95 0.99 0.001 0.1 6"/>
    <pair geom1="mecanum_wheel18" geom2="floor" condim="3" friction="0.5 0.5 0.005 0.0001 0.0001" solimp="0.95 0.99 0.001 0.1 6"/>
    <pair geom1="mecanum_wheel19" geom2="floor" condim="3" friction="0.5 0.5 0.005 0.0001 0.0001" solimp="0.95 0.99 0.001 0.1 6"/>
    <pair geom1="mecanum_wheel20" geom2="floor" condim="3" friction="0.5 0.5 0.005 0.0001 0.0001" solimp="0.95 0.99 0.001 0.1 6"/>
    <pair geom1="mecanum_wheel21" geom2="floor" condim="3" friction="0.5 0.5 0.005 0.0001 0.0001" solimp="0.95 0.99 0.001 0.1 6"/>
    <pair geom1="mecanum_wheel22" geom2="floor" condim="3" friction="0.5 0.5 0.005 0.0001 0.0001" solimp="0.95 0.99 0.001 0.1 6"/>
    <pair geom1="mecanum_wheel23" geom2="floor" condim="3" friction="0.5 0.5 0.005 0.0001 0.0001" solimp="0.95 0.99 0.001 0.1 6"/>
    <pair geom1="mecanum_wheel24" geom2="floor" condim="3" friction="0.5 0.5 0.005 0.0001 0.0001" solimp="0.95 0.99 0.001 0.1 6"/>
    <pair geom1="mecanum_wheel25" geom2="floor" condim="3" friction="0.5 0.5 0.005 0.0001 0.0001" solimp="0.95 0.99 0.001 0.1 6"/>
    <pair geom1="mecanum_wheel26" geom2="floor" condim="3" friction="0.5 0.5 0.005 0.0001 0.0001" solimp="0.95 0.99 0.001 0.1 6"/>
    <pair geom1="mecanum_wheel27" geom2="floor" condim="3" friction="0.5 0.5 0.005 0.0001 0.0001" solimp="0.95 0.99 0.001 0.1 6"/>
    <pair geom1="mecanum_wheel28" geom2="floor" condim="3" friction="0.5 0.5 0.005 0.0001 0.0001" solimp="0.95 0.99 0.001 0.1 6"/>
    <pair geom1="mecanum_wheel29" geom2="floor" condim="3" friction="0.5 0.5 0.005 0.0001 0.0001" solimp="0.95 0.99 0.001 0.1 6"/>
    <pair geom1="mecanum_wheel30" geom2="floor" condim="3" friction="0.5 0.5 0.005 0.0001 0.0001" solimp="0.95 0.99 0.001 0.1 6"/>
    <pair geom1="mecanum_wheel31" geom2="floor" condim="3" friction="0.5 0.5 0.005 0.0001 0.0001" solimp="0.95 0.99 0.001 0.1 6"/>
    <pair geom1="mecanum_wheel32" geom2="floor" condim="3" friction="0.5 0.5 0.005 0.0001 0.0001" solimp="0.95 0.99 0.001 0.1 6"/>
  </contact>
  <tendon>
    <fixed name="left_split">
      <joint joint="left_finger_1_joint" coef="0.5"/>
      <joint joint="left_finger_2_joint" coef="0.5"/>
    </fixed>
  </tendon>
  <tendon>
    <fixed name="right_split">
      <joint joint="right_finger_1_joint" coef="0.5"/>
      <joint joint="right_finger_2_joint" coef="0.5"/>
    </fixed>
  </tendon>
  <equality>
    <joint joint1="left_finger_1_joint" joint2="left_finger_2_joint" polycoef="0 1 0 0 0" solimp="0.95 0.99 0.001" solref="0.005 1"/>
  </equality>
  <equality>
    <joint joint1="right_finger_1_joint" joint2="right_finger_2_joint" polycoef="0 1 0 0 0" solimp="0.95 0.99 0.001" solref="0.005 1"/>
  </equality>
  <tendon>
    <fixed name="left_lift_middle_mimic_higher">
      <joint joint="left_ewellix_lift_lower_to_higher" coef="0.5"/>
      <joint joint="left_middle_mimic_higher" coef="0.5"/>
    </fixed>
  </tendon>
  <tendon>
    <fixed name="right_lift_middle_mimic_higher">
      <joint joint="right_ewellix_lift_lower_to_higher" coef="0.5"/>
      <joint joint="right_middle_mimic_higher" coef="0.5"/>
    </fixed>
  </tendon>
  <equality>
    <joint name="left_upper_mimic_lower" joint1="left_ewellix_lift_lower_to_higher" joint2="left_middle_mimic_higher" polycoef="0 2 0 0 0"/>
  </equality>
  <equality>
    <joint name="right_upper_mimic_lower" joint1="right_ewellix_lift_lower_to_higher" joint2="right_middle_mimic_higher" polycoef="0 2 0 0 0"/>
  </equality>
  <sensor>
    <force name="left_ur_arm_tcp_fts_sensor_force" site="left_ur_arm_ft_frame"/>
    <torque name="left_ur_arm_tcp_fts_sensor_torque" site="left_ur_arm_ft_frame"/>
  </sensor>
  <sensor>
    <force name="right_ur_arm_tcp_fts_sensor_force" site="right_ur_arm_ft_frame"/>
    <torque name="right_ur_arm_tcp_fts_sensor_torque" site="right_ur_arm_ft_frame"/>
  </sensor>
  <sensor>
    <framequat name="imu_sensor_quat" objtype="site" objname="imu_0_link"/>
    <gyro name="imu_sensor_gyro" site="imu_0_link"/>
    <accelerometer name="imu_sensor_accel" site="imu_0_link"/>
  </sensor>
  <sensor>
    <rangefinder name="lidar2d_0" site="lidar2d_0"/>
  </sensor>
</mujoco>